[2025-07-24T15:39:01.344+0000] {taskinstance.py:1956} INFO - Dependencies all met for dep_context=non-requeueable deps ti=<TaskInstance: tune_stream_dag.Load_time_dim_table scheduled__2023-01-01T10:00:00+00:00 [queued]>
[2025-07-24T15:39:01.371+0000] {taskinstance.py:1956} INFO - Dependencies all met for dep_context=requeueable deps ti=<TaskInstance: tune_stream_dag.Load_time_dim_table scheduled__2023-01-01T10:00:00+00:00 [queued]>
[2025-07-24T15:39:01.373+0000] {taskinstance.py:2170} INFO - Starting attempt 2 of 4
[2025-07-24T15:39:01.413+0000] {taskinstance.py:2191} INFO - Executing <Task(PythonOperator): Load_time_dim_table> on 2023-01-01 10:00:00+00:00
[2025-07-24T15:39:01.434+0000] {standard_task_runner.py:60} INFO - Started process 547 to run task
[2025-07-24T15:39:01.443+0000] {standard_task_runner.py:87} INFO - Running: ['***', 'tasks', 'run', 'tune_stream_dag', 'Load_time_dim_table', 'scheduled__2023-01-01T10:00:00+00:00', '--job-id', '1064', '--raw', '--subdir', 'DAGS_FOLDER/etl_pipeline.py', '--cfg-path', '/tmp/tmpfq4ahv6r']
[2025-07-24T15:39:01.457+0000] {standard_task_runner.py:88} INFO - Job 1064: Subtask Load_time_dim_table
[2025-07-24T15:39:01.664+0000] {task_command.py:423} INFO - Running <TaskInstance: tune_stream_dag.Load_time_dim_table scheduled__2023-01-01T10:00:00+00:00 [running]> on host c53547d84df1
[2025-07-24T15:39:01.862+0000] {taskinstance.py:2480} INFO - Exporting env vars: AIRFLOW_CTX_DAG_OWNER='genz-legend' AIRFLOW_CTX_DAG_ID='tune_stream_dag' AIRFLOW_CTX_TASK_ID='Load_time_dim_table' AIRFLOW_CTX_EXECUTION_DATE='2023-01-01T10:00:00+00:00' AIRFLOW_CTX_TRY_NUMBER='2' AIRFLOW_CTX_DAG_RUN_ID='scheduled__2023-01-01T10:00:00+00:00'
[2025-07-24T15:39:01.879+0000] {taskinstance.py:2698} ERROR - Task failed with exception
Traceback (most recent call last):
  File "/home/airflow/.local/lib/python3.8/site-packages/airflow/models/taskinstance.py", line 433, in _execute_task
    result = execute_callable(context=context, **execute_callable_kwargs)
  File "/home/airflow/.local/lib/python3.8/site-packages/airflow/operators/python.py", line 199, in execute
    return_value = self.execute_callable()
  File "/home/airflow/.local/lib/python3.8/site-packages/airflow/operators/python.py", line 216, in execute_callable
    return self.python_callable(*self.op_args, **self.op_kwargs)
  File "/opt/airflow/dags/etl_pipeline.py", line 197, in <lambda>
    python_callable=lambda: load_table(SqlQueries.time_table_insert, 'time'),
  File "/opt/airflow/dags/etl_pipeline.py", line 132, in load_table
    cur.execute(f"INSERT INTO {table} {query}")
psycopg2.errors.InvalidParameterValue: timestamp units "dayofweek" not recognized

[2025-07-24T15:39:01.915+0000] {taskinstance.py:1138} INFO - Marking task as UP_FOR_RETRY. dag_id=tune_stream_dag, task_id=Load_time_dim_table, execution_date=20230101T100000, start_date=20250724T153901, end_date=20250724T153901
[2025-07-24T15:39:01.941+0000] {standard_task_runner.py:107} ERROR - Failed to execute job 1064 for task Load_time_dim_table (timestamp units "dayofweek" not recognized
; 547)
[2025-07-24T15:39:01.994+0000] {local_task_job_runner.py:234} INFO - Task exited with return code 1
[2025-07-24T15:39:02.191+0000] {taskinstance.py:3280} INFO - 0 downstream tasks scheduled from follow-on schedule check
[2025-07-24T16:23:10.248+0000] {taskinstance.py:1956} INFO - Dependencies all met for dep_context=non-requeueable deps ti=<TaskInstance: tune_stream_dag.Load_time_dim_table scheduled__2023-01-01T10:00:00+00:00 [queued]>
[2025-07-24T16:23:10.261+0000] {taskinstance.py:1956} INFO - Dependencies all met for dep_context=requeueable deps ti=<TaskInstance: tune_stream_dag.Load_time_dim_table scheduled__2023-01-01T10:00:00+00:00 [queued]>
[2025-07-24T16:23:10.262+0000] {taskinstance.py:2170} INFO - Starting attempt 2 of 4
[2025-07-24T16:23:10.273+0000] {taskinstance.py:2191} INFO - Executing <Task(PythonOperator): Load_time_dim_table> on 2023-01-01 10:00:00+00:00
[2025-07-24T16:23:10.279+0000] {standard_task_runner.py:60} INFO - Started process 671 to run task
[2025-07-24T16:23:10.282+0000] {standard_task_runner.py:87} INFO - Running: ['***', 'tasks', 'run', 'tune_stream_dag', 'Load_time_dim_table', 'scheduled__2023-01-01T10:00:00+00:00', '--job-id', '1492', '--raw', '--subdir', 'DAGS_FOLDER/etl_pipeline.py', '--cfg-path', '/tmp/tmph707_ozz']
[2025-07-24T16:23:10.286+0000] {standard_task_runner.py:88} INFO - Job 1492: Subtask Load_time_dim_table
[2025-07-24T16:23:10.351+0000] {task_command.py:423} INFO - Running <TaskInstance: tune_stream_dag.Load_time_dim_table scheduled__2023-01-01T10:00:00+00:00 [running]> on host c53547d84df1
[2025-07-24T16:23:10.421+0000] {taskinstance.py:2480} INFO - Exporting env vars: AIRFLOW_CTX_DAG_OWNER='genz-legend' AIRFLOW_CTX_DAG_ID='tune_stream_dag' AIRFLOW_CTX_TASK_ID='Load_time_dim_table' AIRFLOW_CTX_EXECUTION_DATE='2023-01-01T10:00:00+00:00' AIRFLOW_CTX_TRY_NUMBER='2' AIRFLOW_CTX_DAG_RUN_ID='scheduled__2023-01-01T10:00:00+00:00'
[2025-07-24T16:23:10.439+0000] {taskinstance.py:2698} ERROR - Task failed with exception
Traceback (most recent call last):
  File "/home/airflow/.local/lib/python3.8/site-packages/airflow/models/taskinstance.py", line 433, in _execute_task
    result = execute_callable(context=context, **execute_callable_kwargs)
  File "/home/airflow/.local/lib/python3.8/site-packages/airflow/operators/python.py", line 199, in execute
    return_value = self.execute_callable()
  File "/home/airflow/.local/lib/python3.8/site-packages/airflow/operators/python.py", line 216, in execute_callable
    return self.python_callable(*self.op_args, **self.op_kwargs)
  File "/opt/airflow/dags/etl_pipeline.py", line 197, in <lambda>
    python_callable=lambda: load_table(SqlQueries.time_table_insert, 'time'),
  File "/opt/airflow/dags/etl_pipeline.py", line 132, in load_table
    cur.execute(f"INSERT INTO {table} {query}")
psycopg2.errors.UniqueViolation: duplicate key value violates unique constraint "time_pkey"
DETAIL:  Key (start_time)=(2018-11-14 04:53:36) already exists.

[2025-07-24T16:23:10.452+0000] {taskinstance.py:1138} INFO - Marking task as UP_FOR_RETRY. dag_id=tune_stream_dag, task_id=Load_time_dim_table, execution_date=20230101T100000, start_date=20250724T162310, end_date=20250724T162310
[2025-07-24T16:23:10.464+0000] {standard_task_runner.py:107} ERROR - Failed to execute job 1492 for task Load_time_dim_table (duplicate key value violates unique constraint "time_pkey"
DETAIL:  Key (start_time)=(2018-11-14 04:53:36) already exists.
; 671)
[2025-07-24T16:23:10.495+0000] {local_task_job_runner.py:234} INFO - Task exited with return code 1
[2025-07-24T16:23:10.518+0000] {taskinstance.py:3280} INFO - 0 downstream tasks scheduled from follow-on schedule check
[2025-07-24T17:02:22.035+0000] {taskinstance.py:1956} INFO - Dependencies all met for dep_context=non-requeueable deps ti=<TaskInstance: tune_stream_dag.Load_time_dim_table scheduled__2023-01-01T10:00:00+00:00 [queued]>
[2025-07-24T17:02:22.058+0000] {taskinstance.py:1956} INFO - Dependencies all met for dep_context=requeueable deps ti=<TaskInstance: tune_stream_dag.Load_time_dim_table scheduled__2023-01-01T10:00:00+00:00 [queued]>
[2025-07-24T17:02:22.059+0000] {taskinstance.py:2170} INFO - Starting attempt 2 of 4
[2025-07-24T17:02:22.080+0000] {taskinstance.py:2191} INFO - Executing <Task(PythonOperator): Load_time_dim_table> on 2023-01-01 10:00:00+00:00
[2025-07-24T17:02:22.103+0000] {standard_task_runner.py:60} INFO - Started process 651 to run task
[2025-07-24T17:02:22.109+0000] {standard_task_runner.py:87} INFO - Running: ['***', 'tasks', 'run', 'tune_stream_dag', 'Load_time_dim_table', 'scheduled__2023-01-01T10:00:00+00:00', '--job-id', '1881', '--raw', '--subdir', 'DAGS_FOLDER/etl_pipeline.py', '--cfg-path', '/tmp/tmpt1mlbmqa']
[2025-07-24T17:02:22.114+0000] {standard_task_runner.py:88} INFO - Job 1881: Subtask Load_time_dim_table
[2025-07-24T17:02:22.271+0000] {task_command.py:423} INFO - Running <TaskInstance: tune_stream_dag.Load_time_dim_table scheduled__2023-01-01T10:00:00+00:00 [running]> on host 5def55d2a1b5
[2025-07-24T17:02:22.542+0000] {taskinstance.py:2480} INFO - Exporting env vars: AIRFLOW_CTX_DAG_OWNER='genz-legend' AIRFLOW_CTX_DAG_ID='tune_stream_dag' AIRFLOW_CTX_TASK_ID='Load_time_dim_table' AIRFLOW_CTX_EXECUTION_DATE='2023-01-01T10:00:00+00:00' AIRFLOW_CTX_TRY_NUMBER='2' AIRFLOW_CTX_DAG_RUN_ID='scheduled__2023-01-01T10:00:00+00:00'
[2025-07-24T17:02:22.626+0000] {taskinstance.py:2698} ERROR - Task failed with exception
Traceback (most recent call last):
  File "/home/airflow/.local/lib/python3.8/site-packages/airflow/models/taskinstance.py", line 433, in _execute_task
    result = execute_callable(context=context, **execute_callable_kwargs)
  File "/home/airflow/.local/lib/python3.8/site-packages/airflow/operators/python.py", line 199, in execute
    return_value = self.execute_callable()
  File "/home/airflow/.local/lib/python3.8/site-packages/airflow/operators/python.py", line 216, in execute_callable
    return self.python_callable(*self.op_args, **self.op_kwargs)
  File "/opt/airflow/dags/etl_pipeline.py", line 197, in <lambda>
    python_callable=lambda: load_table(SqlQueries.time_table_insert, 'time'),
  File "/opt/airflow/dags/etl_pipeline.py", line 132, in load_table
    cur.execute(f"INSERT INTO {table} {query}")
psycopg2.errors.UniqueViolation: duplicate key value violates unique constraint "time_pkey"
DETAIL:  Key (start_time)=(2018-11-14 04:53:36) already exists.

[2025-07-24T17:02:22.673+0000] {taskinstance.py:1138} INFO - Marking task as UP_FOR_RETRY. dag_id=tune_stream_dag, task_id=Load_time_dim_table, execution_date=20230101T100000, start_date=20250724T170222, end_date=20250724T170222
[2025-07-24T17:02:22.743+0000] {standard_task_runner.py:107} ERROR - Failed to execute job 1881 for task Load_time_dim_table (duplicate key value violates unique constraint "time_pkey"
DETAIL:  Key (start_time)=(2018-11-14 04:53:36) already exists.
; 651)
[2025-07-24T17:02:22.844+0000] {local_task_job_runner.py:234} INFO - Task exited with return code 1
[2025-07-24T17:02:22.927+0000] {taskinstance.py:3280} INFO - 0 downstream tasks scheduled from follow-on schedule check
