[2025-07-24T16:04:57.650+0000] {taskinstance.py:1956} INFO - Dependencies all met for dep_context=non-requeueable deps ti=<TaskInstance: tune_stream_dag.Load_user_dim_table scheduled__2023-01-01T23:00:00+00:00 [queued]>
[2025-07-24T16:04:57.764+0000] {taskinstance.py:1956} INFO - Dependencies all met for dep_context=requeueable deps ti=<TaskInstance: tune_stream_dag.Load_user_dim_table scheduled__2023-01-01T23:00:00+00:00 [queued]>
[2025-07-24T16:04:57.778+0000] {taskinstance.py:2170} INFO - Starting attempt 2 of 4
[2025-07-24T16:04:57.922+0000] {taskinstance.py:2191} INFO - Executing <Task(PythonOperator): Load_user_dim_table> on 2023-01-01 23:00:00+00:00
[2025-07-24T16:04:57.977+0000] {standard_task_runner.py:60} INFO - Started process 1706 to run task
[2025-07-24T16:04:57.989+0000] {standard_task_runner.py:87} INFO - Running: ['***', 'tasks', 'run', 'tune_stream_dag', 'Load_user_dim_table', 'scheduled__2023-01-01T23:00:00+00:00', '--job-id', '1320', '--raw', '--subdir', 'DAGS_FOLDER/etl_pipeline.py', '--cfg-path', '/tmp/tmpncyk4tsg']
[2025-07-24T16:04:58.000+0000] {standard_task_runner.py:88} INFO - Job 1320: Subtask Load_user_dim_table
[2025-07-24T16:04:58.393+0000] {task_command.py:423} INFO - Running <TaskInstance: tune_stream_dag.Load_user_dim_table scheduled__2023-01-01T23:00:00+00:00 [running]> on host c53547d84df1
[2025-07-24T16:04:58.871+0000] {taskinstance.py:2480} INFO - Exporting env vars: AIRFLOW_CTX_DAG_OWNER='genz-legend' AIRFLOW_CTX_DAG_ID='tune_stream_dag' AIRFLOW_CTX_TASK_ID='Load_user_dim_table' AIRFLOW_CTX_EXECUTION_DATE='2023-01-01T23:00:00+00:00' AIRFLOW_CTX_TRY_NUMBER='2' AIRFLOW_CTX_DAG_RUN_ID='scheduled__2023-01-01T23:00:00+00:00'
[2025-07-24T16:04:58.938+0000] {taskinstance.py:2698} ERROR - Task failed with exception
Traceback (most recent call last):
  File "/home/airflow/.local/lib/python3.8/site-packages/airflow/models/taskinstance.py", line 433, in _execute_task
    result = execute_callable(context=context, **execute_callable_kwargs)
  File "/home/airflow/.local/lib/python3.8/site-packages/airflow/operators/python.py", line 199, in execute
    return_value = self.execute_callable()
  File "/home/airflow/.local/lib/python3.8/site-packages/airflow/operators/python.py", line 216, in execute_callable
    return self.python_callable(*self.op_args, **self.op_kwargs)
  File "/opt/airflow/dags/etl_pipeline.py", line 179, in <lambda>
    python_callable=lambda: load_table(SqlQueries.user_table_insert, 'users'),
  File "/opt/airflow/dags/etl_pipeline.py", line 132, in load_table
    cur.execute(f"INSERT INTO {table} {query}")
psycopg2.errors.UniqueViolation: duplicate key value violates unique constraint "users_pkey"
DETAIL:  Key (userid)=(88) already exists.

[2025-07-24T16:04:59.067+0000] {taskinstance.py:1138} INFO - Marking task as UP_FOR_RETRY. dag_id=tune_stream_dag, task_id=Load_user_dim_table, execution_date=20230101T230000, start_date=20250724T160457, end_date=20250724T160459
[2025-07-24T16:04:59.141+0000] {standard_task_runner.py:107} ERROR - Failed to execute job 1320 for task Load_user_dim_table (duplicate key value violates unique constraint "users_pkey"
DETAIL:  Key (userid)=(88) already exists.
; 1706)
[2025-07-24T16:04:59.223+0000] {local_task_job_runner.py:234} INFO - Task exited with return code 1
[2025-07-24T16:04:59.464+0000] {taskinstance.py:3280} INFO - 0 downstream tasks scheduled from follow-on schedule check
[2025-07-24T16:42:23.803+0000] {taskinstance.py:1956} INFO - Dependencies all met for dep_context=non-requeueable deps ti=<TaskInstance: tune_stream_dag.Load_user_dim_table scheduled__2023-01-01T23:00:00+00:00 [queued]>
[2025-07-24T16:42:23.836+0000] {taskinstance.py:1956} INFO - Dependencies all met for dep_context=requeueable deps ti=<TaskInstance: tune_stream_dag.Load_user_dim_table scheduled__2023-01-01T23:00:00+00:00 [queued]>
[2025-07-24T16:42:23.843+0000] {taskinstance.py:2170} INFO - Starting attempt 2 of 4
[2025-07-24T16:42:23.884+0000] {taskinstance.py:2191} INFO - Executing <Task(PythonOperator): Load_user_dim_table> on 2023-01-01 23:00:00+00:00
[2025-07-24T16:42:23.900+0000] {standard_task_runner.py:60} INFO - Started process 188 to run task
[2025-07-24T16:42:23.910+0000] {standard_task_runner.py:87} INFO - Running: ['***', 'tasks', 'run', 'tune_stream_dag', 'Load_user_dim_table', 'scheduled__2023-01-01T23:00:00+00:00', '--job-id', '1706', '--raw', '--subdir', 'DAGS_FOLDER/etl_pipeline.py', '--cfg-path', '/tmp/tmpnkp12c87']
[2025-07-24T16:42:23.922+0000] {standard_task_runner.py:88} INFO - Job 1706: Subtask Load_user_dim_table
[2025-07-24T16:42:24.163+0000] {task_command.py:423} INFO - Running <TaskInstance: tune_stream_dag.Load_user_dim_table scheduled__2023-01-01T23:00:00+00:00 [running]> on host 5def55d2a1b5
[2025-07-24T16:42:24.341+0000] {taskinstance.py:2480} INFO - Exporting env vars: AIRFLOW_CTX_DAG_OWNER='genz-legend' AIRFLOW_CTX_DAG_ID='tune_stream_dag' AIRFLOW_CTX_TASK_ID='Load_user_dim_table' AIRFLOW_CTX_EXECUTION_DATE='2023-01-01T23:00:00+00:00' AIRFLOW_CTX_TRY_NUMBER='2' AIRFLOW_CTX_DAG_RUN_ID='scheduled__2023-01-01T23:00:00+00:00'
[2025-07-24T16:42:24.400+0000] {taskinstance.py:2698} ERROR - Task failed with exception
Traceback (most recent call last):
  File "/home/airflow/.local/lib/python3.8/site-packages/airflow/models/taskinstance.py", line 433, in _execute_task
    result = execute_callable(context=context, **execute_callable_kwargs)
  File "/home/airflow/.local/lib/python3.8/site-packages/airflow/operators/python.py", line 199, in execute
    return_value = self.execute_callable()
  File "/home/airflow/.local/lib/python3.8/site-packages/airflow/operators/python.py", line 216, in execute_callable
    return self.python_callable(*self.op_args, **self.op_kwargs)
  File "/opt/airflow/dags/etl_pipeline.py", line 179, in <lambda>
    python_callable=lambda: load_table(SqlQueries.user_table_insert, 'users'),
  File "/opt/airflow/dags/etl_pipeline.py", line 132, in load_table
    cur.execute(f"INSERT INTO {table} {query}")
psycopg2.errors.UniqueViolation: duplicate key value violates unique constraint "users_pkey"
DETAIL:  Key (userid)=(88) already exists.

[2025-07-24T16:42:24.460+0000] {taskinstance.py:1138} INFO - Marking task as UP_FOR_RETRY. dag_id=tune_stream_dag, task_id=Load_user_dim_table, execution_date=20230101T230000, start_date=20250724T164223, end_date=20250724T164224
[2025-07-24T16:42:24.500+0000] {standard_task_runner.py:107} ERROR - Failed to execute job 1706 for task Load_user_dim_table (duplicate key value violates unique constraint "users_pkey"
DETAIL:  Key (userid)=(88) already exists.
; 188)
[2025-07-24T16:42:24.547+0000] {local_task_job_runner.py:234} INFO - Task exited with return code 1
[2025-07-24T16:42:24.646+0000] {taskinstance.py:3280} INFO - 0 downstream tasks scheduled from follow-on schedule check
[2025-07-24T17:19:11.615+0000] {taskinstance.py:1956} INFO - Dependencies all met for dep_context=non-requeueable deps ti=<TaskInstance: tune_stream_dag.Load_user_dim_table scheduled__2023-01-01T23:00:00+00:00 [queued]>
[2025-07-24T17:19:12.256+0000] {taskinstance.py:1956} INFO - Dependencies all met for dep_context=requeueable deps ti=<TaskInstance: tune_stream_dag.Load_user_dim_table scheduled__2023-01-01T23:00:00+00:00 [queued]>
[2025-07-24T17:19:12.368+0000] {taskinstance.py:2170} INFO - Starting attempt 2 of 4
[2025-07-24T17:19:16.203+0000] {taskinstance.py:2191} INFO - Executing <Task(PythonOperator): Load_user_dim_table> on 2023-01-01 23:00:00+00:00
[2025-07-24T17:19:18.404+0000] {standard_task_runner.py:60} INFO - Started process 1808 to run task
[2025-07-24T17:19:20.777+0000] {standard_task_runner.py:87} INFO - Running: ['***', 'tasks', 'run', 'tune_stream_dag', 'Load_user_dim_table', 'scheduled__2023-01-01T23:00:00+00:00', '--job-id', '2178', '--raw', '--subdir', 'DAGS_FOLDER/etl_pipeline.py', '--cfg-path', '/tmp/tmpm8f5xhuo']
[2025-07-24T17:19:20.996+0000] {standard_task_runner.py:88} INFO - Job 2178: Subtask Load_user_dim_table
[2025-07-24T17:19:29.234+0000] {task_command.py:423} INFO - Running <TaskInstance: tune_stream_dag.Load_user_dim_table scheduled__2023-01-01T23:00:00+00:00 [running]> on host 5def55d2a1b5
[2025-07-24T17:20:16.064+0000] {taskinstance.py:2480} INFO - Exporting env vars: AIRFLOW_CTX_DAG_OWNER='genz-legend' AIRFLOW_CTX_DAG_ID='tune_stream_dag' AIRFLOW_CTX_TASK_ID='Load_user_dim_table' AIRFLOW_CTX_EXECUTION_DATE='2023-01-01T23:00:00+00:00' AIRFLOW_CTX_TRY_NUMBER='2' AIRFLOW_CTX_DAG_RUN_ID='scheduled__2023-01-01T23:00:00+00:00'
[2025-07-24T17:20:37.075+0000] {python.py:201} INFO - Done. Returned value was: None
[2025-07-24T17:20:37.386+0000] {taskinstance.py:1138} INFO - Marking task as SUCCESS. dag_id=tune_stream_dag, task_id=Load_user_dim_table, execution_date=20230101T230000, start_date=20250724T171911, end_date=20250724T172037
[2025-07-24T17:20:37.559+0000] {local_task_job_runner.py:234} INFO - Task exited with return code 0
[2025-07-24T17:20:37.664+0000] {taskinstance.py:3280} INFO - 1 downstream tasks scheduled from follow-on schedule check
