[2025-07-24T16:33:20.345+0000] {taskinstance.py:1956} INFO - Dependencies all met for dep_context=non-requeueable deps ti=<TaskInstance: tune_stream_dag.Load_time_dim_table scheduled__2023-01-01T05:00:00+00:00 [queued]>
[2025-07-24T16:33:20.391+0000] {taskinstance.py:1956} INFO - Dependencies all met for dep_context=requeueable deps ti=<TaskInstance: tune_stream_dag.Load_time_dim_table scheduled__2023-01-01T05:00:00+00:00 [queued]>
[2025-07-24T16:33:20.396+0000] {taskinstance.py:2170} INFO - Starting attempt 4 of 4
[2025-07-24T16:33:20.487+0000] {taskinstance.py:2191} INFO - Executing <Task(PythonOperator): Load_time_dim_table> on 2023-01-01 05:00:00+00:00
[2025-07-24T16:33:20.560+0000] {standard_task_runner.py:60} INFO - Started process 1034 to run task
[2025-07-24T16:33:20.591+0000] {standard_task_runner.py:87} INFO - Running: ['***', 'tasks', 'run', 'tune_stream_dag', 'Load_time_dim_table', 'scheduled__2023-01-01T05:00:00+00:00', '--job-id', '1553', '--raw', '--subdir', 'DAGS_FOLDER/etl_pipeline.py', '--cfg-path', '/tmp/tmptzu6p266']
[2025-07-24T16:33:20.613+0000] {standard_task_runner.py:88} INFO - Job 1553: Subtask Load_time_dim_table
[2025-07-24T16:33:20.841+0000] {task_command.py:423} INFO - Running <TaskInstance: tune_stream_dag.Load_time_dim_table scheduled__2023-01-01T05:00:00+00:00 [running]> on host c53547d84df1
[2025-07-24T16:33:21.180+0000] {taskinstance.py:2480} INFO - Exporting env vars: AIRFLOW_CTX_DAG_OWNER='genz-legend' AIRFLOW_CTX_DAG_ID='tune_stream_dag' AIRFLOW_CTX_TASK_ID='Load_time_dim_table' AIRFLOW_CTX_EXECUTION_DATE='2023-01-01T05:00:00+00:00' AIRFLOW_CTX_TRY_NUMBER='4' AIRFLOW_CTX_DAG_RUN_ID='scheduled__2023-01-01T05:00:00+00:00'
[2025-07-24T16:33:21.320+0000] {taskinstance.py:2698} ERROR - Task failed with exception
Traceback (most recent call last):
  File "/home/airflow/.local/lib/python3.8/site-packages/airflow/models/taskinstance.py", line 433, in _execute_task
    result = execute_callable(context=context, **execute_callable_kwargs)
  File "/home/airflow/.local/lib/python3.8/site-packages/airflow/operators/python.py", line 199, in execute
    return_value = self.execute_callable()
  File "/home/airflow/.local/lib/python3.8/site-packages/airflow/operators/python.py", line 216, in execute_callable
    return self.python_callable(*self.op_args, **self.op_kwargs)
  File "/opt/airflow/dags/etl_pipeline.py", line 197, in <lambda>
    python_callable=lambda: load_table(SqlQueries.time_table_insert, 'time'),
  File "/opt/airflow/dags/etl_pipeline.py", line 132, in load_table
    cur.execute(f"INSERT INTO {table} {query}")
psycopg2.errors.UniqueViolation: duplicate key value violates unique constraint "time_pkey"
DETAIL:  Key (start_time)=(2018-11-14 04:53:36) already exists.

[2025-07-24T16:33:21.399+0000] {taskinstance.py:1138} INFO - Marking task as FAILED. dag_id=tune_stream_dag, task_id=Load_time_dim_table, execution_date=20230101T050000, start_date=20250724T163320, end_date=20250724T163321
[2025-07-24T16:33:21.473+0000] {standard_task_runner.py:107} ERROR - Failed to execute job 1553 for task Load_time_dim_table (duplicate key value violates unique constraint "time_pkey"
DETAIL:  Key (start_time)=(2018-11-14 04:53:36) already exists.
; 1034)
[2025-07-24T16:33:21.515+0000] {local_task_job_runner.py:234} INFO - Task exited with return code 1
[2025-07-24T16:33:21.556+0000] {taskinstance.py:3280} INFO - 0 downstream tasks scheduled from follow-on schedule check
[2025-07-24T17:12:13.954+0000] {taskinstance.py:1956} INFO - Dependencies all met for dep_context=non-requeueable deps ti=<TaskInstance: tune_stream_dag.Load_time_dim_table scheduled__2023-01-01T05:00:00+00:00 [queued]>
[2025-07-24T17:12:13.978+0000] {taskinstance.py:1956} INFO - Dependencies all met for dep_context=requeueable deps ti=<TaskInstance: tune_stream_dag.Load_time_dim_table scheduled__2023-01-01T05:00:00+00:00 [queued]>
[2025-07-24T17:12:13.979+0000] {taskinstance.py:2170} INFO - Starting attempt 4 of 4
[2025-07-24T17:12:14.118+0000] {taskinstance.py:2191} INFO - Executing <Task(PythonOperator): Load_time_dim_table> on 2023-01-01 05:00:00+00:00
[2025-07-24T17:12:14.137+0000] {standard_task_runner.py:60} INFO - Started process 971 to run task
[2025-07-24T17:12:14.206+0000] {standard_task_runner.py:87} INFO - Running: ['***', 'tasks', 'run', 'tune_stream_dag', 'Load_time_dim_table', 'scheduled__2023-01-01T05:00:00+00:00', '--job-id', '1938', '--raw', '--subdir', 'DAGS_FOLDER/etl_pipeline.py', '--cfg-path', '/tmp/tmpeqrxs5ls']
[2025-07-24T17:12:14.233+0000] {standard_task_runner.py:88} INFO - Job 1938: Subtask Load_time_dim_table
[2025-07-24T17:12:14.436+0000] {task_command.py:423} INFO - Running <TaskInstance: tune_stream_dag.Load_time_dim_table scheduled__2023-01-01T05:00:00+00:00 [running]> on host 5def55d2a1b5
[2025-07-24T17:12:14.667+0000] {taskinstance.py:2480} INFO - Exporting env vars: AIRFLOW_CTX_DAG_OWNER='genz-legend' AIRFLOW_CTX_DAG_ID='tune_stream_dag' AIRFLOW_CTX_TASK_ID='Load_time_dim_table' AIRFLOW_CTX_EXECUTION_DATE='2023-01-01T05:00:00+00:00' AIRFLOW_CTX_TRY_NUMBER='4' AIRFLOW_CTX_DAG_RUN_ID='scheduled__2023-01-01T05:00:00+00:00'
[2025-07-24T17:12:14.729+0000] {taskinstance.py:2698} ERROR - Task failed with exception
Traceback (most recent call last):
  File "/home/airflow/.local/lib/python3.8/site-packages/airflow/models/taskinstance.py", line 433, in _execute_task
    result = execute_callable(context=context, **execute_callable_kwargs)
  File "/home/airflow/.local/lib/python3.8/site-packages/airflow/operators/python.py", line 199, in execute
    return_value = self.execute_callable()
  File "/home/airflow/.local/lib/python3.8/site-packages/airflow/operators/python.py", line 216, in execute_callable
    return self.python_callable(*self.op_args, **self.op_kwargs)
  File "/opt/airflow/dags/etl_pipeline.py", line 197, in <lambda>
    python_callable=lambda: load_table(SqlQueries.time_table_insert, 'time'),
  File "/opt/airflow/dags/etl_pipeline.py", line 132, in load_table
    cur.execute(f"INSERT INTO {table} {query}")
psycopg2.errors.UniqueViolation: duplicate key value violates unique constraint "time_pkey"
DETAIL:  Key (start_time)=(2018-11-14 04:53:36) already exists.

[2025-07-24T17:12:14.790+0000] {taskinstance.py:1138} INFO - Marking task as FAILED. dag_id=tune_stream_dag, task_id=Load_time_dim_table, execution_date=20230101T050000, start_date=20250724T171213, end_date=20250724T171214
[2025-07-24T17:12:14.820+0000] {standard_task_runner.py:107} ERROR - Failed to execute job 1938 for task Load_time_dim_table (duplicate key value violates unique constraint "time_pkey"
DETAIL:  Key (start_time)=(2018-11-14 04:53:36) already exists.
; 971)
[2025-07-24T17:12:14.862+0000] {local_task_job_runner.py:234} INFO - Task exited with return code 1
[2025-07-24T17:12:14.918+0000] {taskinstance.py:3280} INFO - 0 downstream tasks scheduled from follow-on schedule check
