[2025-07-24T15:05:09.423+0000] {taskinstance.py:1956} INFO - Dependencies all met for dep_context=non-requeueable deps ti=<TaskInstance: tune_stream_dag.Load_songplays_fact_table scheduled__2023-01-04T00:00:00+00:00 [queued]>
[2025-07-24T15:05:09.430+0000] {taskinstance.py:1956} INFO - Dependencies all met for dep_context=requeueable deps ti=<TaskInstance: tune_stream_dag.Load_songplays_fact_table scheduled__2023-01-04T00:00:00+00:00 [queued]>
[2025-07-24T15:05:09.431+0000] {taskinstance.py:2170} INFO - Starting attempt 6 of 8
[2025-07-24T15:05:10.359+0000] {taskinstance.py:2191} INFO - Executing <Task(PythonOperator): Load_songplays_fact_table> on 2023-01-04 00:00:00+00:00
[2025-07-24T15:05:10.618+0000] {standard_task_runner.py:60} INFO - Started process 263 to run task
[2025-07-24T15:05:10.624+0000] {standard_task_runner.py:87} INFO - Running: ['***', 'tasks', 'run', 'tune_stream_dag', 'Load_songplays_fact_table', 'scheduled__2023-01-04T00:00:00+00:00', '--job-id', '773', '--raw', '--subdir', 'DAGS_FOLDER/etl_pipeline.py', '--cfg-path', '/tmp/tmpzwo4bnxk']
[2025-07-24T15:05:10.627+0000] {standard_task_runner.py:88} INFO - Job 773: Subtask Load_songplays_fact_table
[2025-07-24T15:05:12.840+0000] {task_command.py:423} INFO - Running <TaskInstance: tune_stream_dag.Load_songplays_fact_table scheduled__2023-01-04T00:00:00+00:00 [running]> on host c53547d84df1
[2025-07-24T15:05:13.103+0000] {taskinstance.py:2480} INFO - Exporting env vars: AIRFLOW_CTX_DAG_OWNER='genz-legend' AIRFLOW_CTX_DAG_ID='tune_stream_dag' AIRFLOW_CTX_TASK_ID='Load_songplays_fact_table' AIRFLOW_CTX_EXECUTION_DATE='2023-01-04T00:00:00+00:00' AIRFLOW_CTX_TRY_NUMBER='6' AIRFLOW_CTX_DAG_RUN_ID='scheduled__2023-01-04T00:00:00+00:00'
[2025-07-24T15:05:20.270+0000] {taskinstance.py:2698} ERROR - Task failed with exception
Traceback (most recent call last):
  File "/home/airflow/.local/lib/python3.8/site-packages/airflow/models/taskinstance.py", line 433, in _execute_task
    result = execute_callable(context=context, **execute_callable_kwargs)
  File "/home/airflow/.local/lib/python3.8/site-packages/airflow/operators/python.py", line 199, in execute
    return_value = self.execute_callable()
  File "/home/airflow/.local/lib/python3.8/site-packages/airflow/operators/python.py", line 216, in execute_callable
    return self.python_callable(*self.op_args, **self.op_kwargs)
  File "/opt/airflow/dags/etl_pipeline.py", line 170, in <lambda>
    python_callable=lambda: load_table(SqlQueries.songplay_table_insert, 'songplays'),
  File "/opt/airflow/dags/etl_pipeline.py", line 129, in load_table
    cur.execute(f"INSERT INTO {table} {query}")
psycopg2.errors.UniqueViolation: duplicate key value violates unique constraint "songplays_pkey"
DETAIL:  Key (playid)=(0c4ee7572a079a9e42e1127b00ad48e4) already exists.

[2025-07-24T15:05:20.284+0000] {taskinstance.py:1138} INFO - Marking task as UP_FOR_RETRY. dag_id=tune_stream_dag, task_id=Load_songplays_fact_table, execution_date=20230104T000000, start_date=20250724T150509, end_date=20250724T150520
[2025-07-24T15:05:20.367+0000] {standard_task_runner.py:107} ERROR - Failed to execute job 773 for task Load_songplays_fact_table (duplicate key value violates unique constraint "songplays_pkey"
DETAIL:  Key (playid)=(0c4ee7572a079a9e42e1127b00ad48e4) already exists.
; 263)
[2025-07-24T15:05:20.390+0000] {local_task_job_runner.py:234} INFO - Task exited with return code 1
[2025-07-24T15:05:20.407+0000] {taskinstance.py:3280} INFO - 0 downstream tasks scheduled from follow-on schedule check
