[2025-07-24T16:47:28.039+0000] {taskinstance.py:1956} INFO - Dependencies all met for dep_context=non-requeueable deps ti=<TaskInstance: tune_stream_dag.Load_user_dim_table scheduled__2023-01-02T06:00:00+00:00 [queued]>
[2025-07-24T16:47:28.058+0000] {taskinstance.py:1956} INFO - Dependencies all met for dep_context=requeueable deps ti=<TaskInstance: tune_stream_dag.Load_user_dim_table scheduled__2023-01-02T06:00:00+00:00 [queued]>
[2025-07-24T16:47:28.060+0000] {taskinstance.py:2170} INFO - Starting attempt 3 of 4
[2025-07-24T16:47:28.086+0000] {taskinstance.py:2191} INFO - Executing <Task(PythonOperator): Load_user_dim_table> on 2023-01-02 06:00:00+00:00
[2025-07-24T16:47:28.104+0000] {standard_task_runner.py:60} INFO - Started process 352 to run task
[2025-07-24T16:47:28.111+0000] {standard_task_runner.py:87} INFO - Running: ['***', 'tasks', 'run', 'tune_stream_dag', 'Load_user_dim_table', 'scheduled__2023-01-02T06:00:00+00:00', '--job-id', '1738', '--raw', '--subdir', 'DAGS_FOLDER/etl_pipeline.py', '--cfg-path', '/tmp/tmph45c_2fg']
[2025-07-24T16:47:28.117+0000] {standard_task_runner.py:88} INFO - Job 1738: Subtask Load_user_dim_table
[2025-07-24T16:47:28.263+0000] {task_command.py:423} INFO - Running <TaskInstance: tune_stream_dag.Load_user_dim_table scheduled__2023-01-02T06:00:00+00:00 [running]> on host 5def55d2a1b5
[2025-07-24T16:47:28.406+0000] {taskinstance.py:2480} INFO - Exporting env vars: AIRFLOW_CTX_DAG_OWNER='genz-legend' AIRFLOW_CTX_DAG_ID='tune_stream_dag' AIRFLOW_CTX_TASK_ID='Load_user_dim_table' AIRFLOW_CTX_EXECUTION_DATE='2023-01-02T06:00:00+00:00' AIRFLOW_CTX_TRY_NUMBER='3' AIRFLOW_CTX_DAG_RUN_ID='scheduled__2023-01-02T06:00:00+00:00'
[2025-07-24T16:47:28.431+0000] {taskinstance.py:2698} ERROR - Task failed with exception
Traceback (most recent call last):
  File "/home/airflow/.local/lib/python3.8/site-packages/airflow/models/taskinstance.py", line 433, in _execute_task
    result = execute_callable(context=context, **execute_callable_kwargs)
  File "/home/airflow/.local/lib/python3.8/site-packages/airflow/operators/python.py", line 199, in execute
    return_value = self.execute_callable()
  File "/home/airflow/.local/lib/python3.8/site-packages/airflow/operators/python.py", line 216, in execute_callable
    return self.python_callable(*self.op_args, **self.op_kwargs)
  File "/opt/airflow/dags/etl_pipeline.py", line 179, in <lambda>
    python_callable=lambda: load_table(SqlQueries.user_table_insert, 'users'),
  File "/opt/airflow/dags/etl_pipeline.py", line 131, in load_table
    cur.execute(f"TRUNCATE TABLE {table}")
psycopg2.errors.UndefinedTable: relation "users" does not exist

[2025-07-24T16:47:28.468+0000] {taskinstance.py:1138} INFO - Marking task as UP_FOR_RETRY. dag_id=tune_stream_dag, task_id=Load_user_dim_table, execution_date=20230102T060000, start_date=20250724T164728, end_date=20250724T164728
[2025-07-24T16:47:28.492+0000] {standard_task_runner.py:107} ERROR - Failed to execute job 1738 for task Load_user_dim_table (relation "users" does not exist
; 352)
[2025-07-24T16:47:28.546+0000] {local_task_job_runner.py:234} INFO - Task exited with return code 1
[2025-07-24T16:47:28.658+0000] {taskinstance.py:3280} INFO - 0 downstream tasks scheduled from follow-on schedule check
