[2025-07-24T13:42:39.911+0000] {taskinstance.py:1956} INFO - Dependencies all met for dep_context=non-requeueable deps ti=<TaskInstance: tune_stream_dag.Load_songplays_fact_table manual__2025-07-22T10:16:36.898393+00:00 [queued]>
[2025-07-24T13:42:39.954+0000] {taskinstance.py:1956} INFO - Dependencies all met for dep_context=requeueable deps ti=<TaskInstance: tune_stream_dag.Load_songplays_fact_table manual__2025-07-22T10:16:36.898393+00:00 [queued]>
[2025-07-24T13:42:40.006+0000] {taskinstance.py:2170} INFO - Starting attempt 2 of 4
[2025-07-24T13:42:40.197+0000] {taskinstance.py:2191} INFO - Executing <Task(PythonOperator): Load_songplays_fact_table> on 2025-07-22 10:16:36.898393+00:00
[2025-07-24T13:42:40.252+0000] {standard_task_runner.py:60} INFO - Started process 147 to run task
[2025-07-24T13:42:40.262+0000] {standard_task_runner.py:87} INFO - Running: ['***', 'tasks', 'run', 'tune_stream_dag', 'Load_songplays_fact_table', 'manual__2025-07-22T10:16:36.898393+00:00', '--job-id', '312', '--raw', '--subdir', 'DAGS_FOLDER/etl_pipeline.py', '--cfg-path', '/tmp/tmpzbhhb5ek']
[2025-07-24T13:42:40.277+0000] {standard_task_runner.py:88} INFO - Job 312: Subtask Load_songplays_fact_table
[2025-07-24T13:42:41.710+0000] {task_command.py:423} INFO - Running <TaskInstance: tune_stream_dag.Load_songplays_fact_table manual__2025-07-22T10:16:36.898393+00:00 [running]> on host a4bcda7cb679
[2025-07-24T13:42:44.488+0000] {taskinstance.py:2480} INFO - Exporting env vars: AIRFLOW_CTX_DAG_OWNER='genz-legend' AIRFLOW_CTX_DAG_ID='tune_stream_dag' AIRFLOW_CTX_TASK_ID='Load_songplays_fact_table' AIRFLOW_CTX_EXECUTION_DATE='2025-07-22T10:16:36.898393+00:00' AIRFLOW_CTX_TRY_NUMBER='2' AIRFLOW_CTX_DAG_RUN_ID='manual__2025-07-22T10:16:36.898393+00:00'
[2025-07-24T13:42:45.004+0000] {taskinstance.py:2698} ERROR - Task failed with exception
Traceback (most recent call last):
  File "/home/airflow/.local/lib/python3.8/site-packages/airflow/models/taskinstance.py", line 433, in _execute_task
    result = execute_callable(context=context, **execute_callable_kwargs)
  File "/home/airflow/.local/lib/python3.8/site-packages/airflow/operators/python.py", line 199, in execute
    return_value = self.execute_callable()
  File "/home/airflow/.local/lib/python3.8/site-packages/airflow/operators/python.py", line 216, in execute_callable
    return self.python_callable(*self.op_args, **self.op_kwargs)
  File "/opt/airflow/dags/etl_pipeline.py", line 168, in <lambda>
    python_callable=lambda: load_table(SqlQueries.songplay_table_insert),
  File "/opt/airflow/dags/etl_pipeline.py", line 127, in load_table
    cur.execute(f"DELETE FROM {query.split()[3]}")
psycopg2.errors.SyntaxError: syntax error at or near ")"
LINE 1: DELETE FROM events.start_time)
                                     ^

[2025-07-24T13:42:45.574+0000] {taskinstance.py:1138} INFO - Marking task as UP_FOR_RETRY. dag_id=tune_stream_dag, task_id=Load_songplays_fact_table, execution_date=20250722T101636, start_date=20250724T134239, end_date=20250724T134245
[2025-07-24T13:42:47.218+0000] {standard_task_runner.py:107} ERROR - Failed to execute job 312 for task Load_songplays_fact_table (syntax error at or near ")"
LINE 1: DELETE FROM events.start_time)
                                     ^
; 147)
[2025-07-24T13:42:47.267+0000] {local_task_job_runner.py:234} INFO - Task exited with return code 1
[2025-07-24T13:42:47.294+0000] {taskinstance.py:3280} INFO - 0 downstream tasks scheduled from follow-on schedule check
