[2025-07-24T15:22:37.673+0000] {taskinstance.py:1956} INFO - Dependencies all met for dep_context=non-requeueable deps ti=<TaskInstance: tune_stream_dag.Load_user_dim_table scheduled__2023-01-04T21:00:00+00:00 [queued]>
[2025-07-24T15:22:37.708+0000] {taskinstance.py:1956} INFO - Dependencies all met for dep_context=requeueable deps ti=<TaskInstance: tune_stream_dag.Load_user_dim_table scheduled__2023-01-04T21:00:00+00:00 [queued]>
[2025-07-24T15:22:38.016+0000] {taskinstance.py:2170} INFO - Starting attempt 1 of 4
[2025-07-24T15:22:38.130+0000] {taskinstance.py:2191} INFO - Executing <Task(PythonOperator): Load_user_dim_table> on 2023-01-04 21:00:00+00:00
[2025-07-24T15:22:38.355+0000] {standard_task_runner.py:60} INFO - Started process 836 to run task
[2025-07-24T15:22:38.406+0000] {standard_task_runner.py:87} INFO - Running: ['***', 'tasks', 'run', 'tune_stream_dag', 'Load_user_dim_table', 'scheduled__2023-01-04T21:00:00+00:00', '--job-id', '876', '--raw', '--subdir', 'DAGS_FOLDER/etl_pipeline.py', '--cfg-path', '/tmp/tmpdmt0axwu']
[2025-07-24T15:22:38.488+0000] {standard_task_runner.py:88} INFO - Job 876: Subtask Load_user_dim_table
[2025-07-24T15:22:38.803+0000] {task_command.py:423} INFO - Running <TaskInstance: tune_stream_dag.Load_user_dim_table scheduled__2023-01-04T21:00:00+00:00 [running]> on host c53547d84df1
[2025-07-24T15:22:39.381+0000] {taskinstance.py:2480} INFO - Exporting env vars: AIRFLOW_CTX_DAG_OWNER='genz-legend' AIRFLOW_CTX_DAG_ID='tune_stream_dag' AIRFLOW_CTX_TASK_ID='Load_user_dim_table' AIRFLOW_CTX_EXECUTION_DATE='2023-01-04T21:00:00+00:00' AIRFLOW_CTX_TRY_NUMBER='1' AIRFLOW_CTX_DAG_RUN_ID='scheduled__2023-01-04T21:00:00+00:00'
[2025-07-24T15:22:39.425+0000] {taskinstance.py:2698} ERROR - Task failed with exception
Traceback (most recent call last):
  File "/home/airflow/.local/lib/python3.8/site-packages/airflow/models/taskinstance.py", line 433, in _execute_task
    result = execute_callable(context=context, **execute_callable_kwargs)
  File "/home/airflow/.local/lib/python3.8/site-packages/airflow/operators/python.py", line 199, in execute
    return_value = self.execute_callable()
  File "/home/airflow/.local/lib/python3.8/site-packages/airflow/operators/python.py", line 216, in execute_callable
    return self.python_callable(*self.op_args, **self.op_kwargs)
  File "/opt/airflow/dags/etl_pipeline.py", line 179, in <lambda>
    python_callable=lambda: load_table(SqlQueries.user_table_insert, 'users'),
  File "/opt/airflow/dags/etl_pipeline.py", line 132, in load_table
    cur.execute(f"INSERT INTO {table} {query}")
psycopg2.errors.UniqueViolation: duplicate key value violates unique constraint "users_pkey"
DETAIL:  Key (userid)=(88) already exists.

[2025-07-24T15:22:39.557+0000] {taskinstance.py:1138} INFO - Marking task as UP_FOR_RETRY. dag_id=tune_stream_dag, task_id=Load_user_dim_table, execution_date=20230104T210000, start_date=20250724T152237, end_date=20250724T152239
[2025-07-24T15:22:41.431+0000] {standard_task_runner.py:107} ERROR - Failed to execute job 876 for task Load_user_dim_table (duplicate key value violates unique constraint "users_pkey"
DETAIL:  Key (userid)=(88) already exists.
; 836)
[2025-07-24T15:22:41.568+0000] {local_task_job_runner.py:234} INFO - Task exited with return code 1
[2025-07-24T15:22:41.947+0000] {taskinstance.py:3280} INFO - 0 downstream tasks scheduled from follow-on schedule check
[2025-07-24T17:33:19.839+0000] {taskinstance.py:1956} INFO - Dependencies all met for dep_context=non-requeueable deps ti=<TaskInstance: tune_stream_dag.Load_user_dim_table scheduled__2023-01-04T21:00:00+00:00 [queued]>
[2025-07-24T17:33:19.894+0000] {taskinstance.py:1956} INFO - Dependencies all met for dep_context=requeueable deps ti=<TaskInstance: tune_stream_dag.Load_user_dim_table scheduled__2023-01-04T21:00:00+00:00 [queued]>
[2025-07-24T17:33:19.902+0000] {taskinstance.py:2170} INFO - Starting attempt 1 of 4
[2025-07-24T17:33:20.012+0000] {taskinstance.py:2191} INFO - Executing <Task(PythonOperator): Load_user_dim_table> on 2023-01-04 21:00:00+00:00
[2025-07-24T17:33:20.064+0000] {standard_task_runner.py:60} INFO - Started process 3382 to run task
[2025-07-24T17:33:20.089+0000] {standard_task_runner.py:87} INFO - Running: ['***', 'tasks', 'run', 'tune_stream_dag', 'Load_user_dim_table', 'scheduled__2023-01-04T21:00:00+00:00', '--job-id', '2649', '--raw', '--subdir', 'DAGS_FOLDER/etl_pipeline.py', '--cfg-path', '/tmp/tmp9km854sr']
[2025-07-24T17:33:20.132+0000] {standard_task_runner.py:88} INFO - Job 2649: Subtask Load_user_dim_table
[2025-07-24T17:33:20.780+0000] {task_command.py:423} INFO - Running <TaskInstance: tune_stream_dag.Load_user_dim_table scheduled__2023-01-04T21:00:00+00:00 [running]> on host 5def55d2a1b5
[2025-07-24T17:33:21.129+0000] {taskinstance.py:2480} INFO - Exporting env vars: AIRFLOW_CTX_DAG_OWNER='genz-legend' AIRFLOW_CTX_DAG_ID='tune_stream_dag' AIRFLOW_CTX_TASK_ID='Load_user_dim_table' AIRFLOW_CTX_EXECUTION_DATE='2023-01-04T21:00:00+00:00' AIRFLOW_CTX_TRY_NUMBER='1' AIRFLOW_CTX_DAG_RUN_ID='scheduled__2023-01-04T21:00:00+00:00'
[2025-07-24T17:33:21.345+0000] {python.py:201} INFO - Done. Returned value was: None
[2025-07-24T17:33:21.404+0000] {taskinstance.py:1138} INFO - Marking task as SUCCESS. dag_id=tune_stream_dag, task_id=Load_user_dim_table, execution_date=20230104T210000, start_date=20250724T173319, end_date=20250724T173321
[2025-07-24T17:33:21.506+0000] {local_task_job_runner.py:234} INFO - Task exited with return code 0
[2025-07-24T17:33:21.642+0000] {taskinstance.py:3280} INFO - 0 downstream tasks scheduled from follow-on schedule check
