[2025-07-24T15:33:50.726+0000] {taskinstance.py:1956} INFO - Dependencies all met for dep_context=non-requeueable deps ti=<TaskInstance: tune_stream_dag.Load_user_dim_table scheduled__2023-01-01T10:00:00+00:00 [queued]>
[2025-07-24T15:33:50.739+0000] {taskinstance.py:1956} INFO - Dependencies all met for dep_context=requeueable deps ti=<TaskInstance: tune_stream_dag.Load_user_dim_table scheduled__2023-01-01T10:00:00+00:00 [queued]>
[2025-07-24T15:33:50.740+0000] {taskinstance.py:2170} INFO - Starting attempt 1 of 4
[2025-07-24T15:33:50.980+0000] {taskinstance.py:2191} INFO - Executing <Task(PythonOperator): Load_user_dim_table> on 2023-01-01 10:00:00+00:00
[2025-07-24T15:33:51.002+0000] {standard_task_runner.py:60} INFO - Started process 351 to run task
[2025-07-24T15:33:51.008+0000] {standard_task_runner.py:87} INFO - Running: ['***', 'tasks', 'run', 'tune_stream_dag', 'Load_user_dim_table', 'scheduled__2023-01-01T10:00:00+00:00', '--job-id', '1023', '--raw', '--subdir', 'DAGS_FOLDER/etl_pipeline.py', '--cfg-path', '/tmp/tmpng3mcs10']
[2025-07-24T15:33:51.210+0000] {standard_task_runner.py:88} INFO - Job 1023: Subtask Load_user_dim_table
[2025-07-24T15:33:51.500+0000] {task_command.py:423} INFO - Running <TaskInstance: tune_stream_dag.Load_user_dim_table scheduled__2023-01-01T10:00:00+00:00 [running]> on host c53547d84df1
[2025-07-24T15:33:51.690+0000] {taskinstance.py:2480} INFO - Exporting env vars: AIRFLOW_CTX_DAG_OWNER='genz-legend' AIRFLOW_CTX_DAG_ID='tune_stream_dag' AIRFLOW_CTX_TASK_ID='Load_user_dim_table' AIRFLOW_CTX_EXECUTION_DATE='2023-01-01T10:00:00+00:00' AIRFLOW_CTX_TRY_NUMBER='1' AIRFLOW_CTX_DAG_RUN_ID='scheduled__2023-01-01T10:00:00+00:00'
[2025-07-24T15:33:51.709+0000] {taskinstance.py:2698} ERROR - Task failed with exception
Traceback (most recent call last):
  File "/home/airflow/.local/lib/python3.8/site-packages/airflow/models/taskinstance.py", line 433, in _execute_task
    result = execute_callable(context=context, **execute_callable_kwargs)
  File "/home/airflow/.local/lib/python3.8/site-packages/airflow/operators/python.py", line 199, in execute
    return_value = self.execute_callable()
  File "/home/airflow/.local/lib/python3.8/site-packages/airflow/operators/python.py", line 216, in execute_callable
    return self.python_callable(*self.op_args, **self.op_kwargs)
  File "/opt/airflow/dags/etl_pipeline.py", line 179, in <lambda>
    python_callable=lambda: load_table(SqlQueries.user_table_insert, 'users'),
  File "/opt/airflow/dags/etl_pipeline.py", line 132, in load_table
    cur.execute(f"INSERT INTO {table} {query}")
psycopg2.errors.UniqueViolation: duplicate key value violates unique constraint "users_pkey"
DETAIL:  Key (userid)=(88) already exists.

[2025-07-24T15:33:51.729+0000] {taskinstance.py:1138} INFO - Marking task as UP_FOR_RETRY. dag_id=tune_stream_dag, task_id=Load_user_dim_table, execution_date=20230101T100000, start_date=20250724T153350, end_date=20250724T153351
[2025-07-24T15:33:51.980+0000] {standard_task_runner.py:107} ERROR - Failed to execute job 1023 for task Load_user_dim_table (duplicate key value violates unique constraint "users_pkey"
DETAIL:  Key (userid)=(88) already exists.
; 351)
[2025-07-24T15:33:52.019+0000] {local_task_job_runner.py:234} INFO - Task exited with return code 1
[2025-07-24T15:33:52.059+0000] {taskinstance.py:3280} INFO - 0 downstream tasks scheduled from follow-on schedule check
[2025-07-24T16:18:06.290+0000] {taskinstance.py:1956} INFO - Dependencies all met for dep_context=non-requeueable deps ti=<TaskInstance: tune_stream_dag.Load_user_dim_table scheduled__2023-01-01T10:00:00+00:00 [queued]>
[2025-07-24T16:18:06.334+0000] {taskinstance.py:1956} INFO - Dependencies all met for dep_context=requeueable deps ti=<TaskInstance: tune_stream_dag.Load_user_dim_table scheduled__2023-01-01T10:00:00+00:00 [queued]>
[2025-07-24T16:18:06.340+0000] {taskinstance.py:2170} INFO - Starting attempt 1 of 4
[2025-07-24T16:18:06.391+0000] {taskinstance.py:2191} INFO - Executing <Task(PythonOperator): Load_user_dim_table> on 2023-01-01 10:00:00+00:00
[2025-07-24T16:18:06.434+0000] {standard_task_runner.py:60} INFO - Started process 478 to run task
[2025-07-24T16:18:06.491+0000] {standard_task_runner.py:87} INFO - Running: ['***', 'tasks', 'run', 'tune_stream_dag', 'Load_user_dim_table', 'scheduled__2023-01-01T10:00:00+00:00', '--job-id', '1444', '--raw', '--subdir', 'DAGS_FOLDER/etl_pipeline.py', '--cfg-path', '/tmp/tmpgp6fwycu']
[2025-07-24T16:18:06.512+0000] {standard_task_runner.py:88} INFO - Job 1444: Subtask Load_user_dim_table
[2025-07-24T16:18:06.901+0000] {task_command.py:423} INFO - Running <TaskInstance: tune_stream_dag.Load_user_dim_table scheduled__2023-01-01T10:00:00+00:00 [running]> on host c53547d84df1
[2025-07-24T16:18:07.968+0000] {taskinstance.py:2480} INFO - Exporting env vars: AIRFLOW_CTX_DAG_OWNER='genz-legend' AIRFLOW_CTX_DAG_ID='tune_stream_dag' AIRFLOW_CTX_TASK_ID='Load_user_dim_table' AIRFLOW_CTX_EXECUTION_DATE='2023-01-01T10:00:00+00:00' AIRFLOW_CTX_TRY_NUMBER='1' AIRFLOW_CTX_DAG_RUN_ID='scheduled__2023-01-01T10:00:00+00:00'
[2025-07-24T16:18:08.344+0000] {taskinstance.py:2698} ERROR - Task failed with exception
Traceback (most recent call last):
  File "/home/airflow/.local/lib/python3.8/site-packages/airflow/models/taskinstance.py", line 433, in _execute_task
    result = execute_callable(context=context, **execute_callable_kwargs)
  File "/home/airflow/.local/lib/python3.8/site-packages/airflow/operators/python.py", line 199, in execute
    return_value = self.execute_callable()
  File "/home/airflow/.local/lib/python3.8/site-packages/airflow/operators/python.py", line 216, in execute_callable
    return self.python_callable(*self.op_args, **self.op_kwargs)
  File "/opt/airflow/dags/etl_pipeline.py", line 179, in <lambda>
    python_callable=lambda: load_table(SqlQueries.user_table_insert, 'users'),
  File "/opt/airflow/dags/etl_pipeline.py", line 132, in load_table
    cur.execute(f"INSERT INTO {table} {query}")
psycopg2.errors.UniqueViolation: duplicate key value violates unique constraint "users_pkey"
DETAIL:  Key (userid)=(88) already exists.

[2025-07-24T16:18:08.376+0000] {taskinstance.py:1138} INFO - Marking task as UP_FOR_RETRY. dag_id=tune_stream_dag, task_id=Load_user_dim_table, execution_date=20230101T100000, start_date=20250724T161806, end_date=20250724T161808
[2025-07-24T16:18:08.762+0000] {standard_task_runner.py:107} ERROR - Failed to execute job 1444 for task Load_user_dim_table (duplicate key value violates unique constraint "users_pkey"
DETAIL:  Key (userid)=(88) already exists.
; 478)
[2025-07-24T16:18:08.895+0000] {local_task_job_runner.py:234} INFO - Task exited with return code 1
[2025-07-24T16:18:08.959+0000] {taskinstance.py:3280} INFO - 0 downstream tasks scheduled from follow-on schedule check
[2025-07-24T16:57:15.350+0000] {taskinstance.py:1956} INFO - Dependencies all met for dep_context=non-requeueable deps ti=<TaskInstance: tune_stream_dag.Load_user_dim_table scheduled__2023-01-01T10:00:00+00:00 [queued]>
[2025-07-24T16:57:15.383+0000] {taskinstance.py:1956} INFO - Dependencies all met for dep_context=requeueable deps ti=<TaskInstance: tune_stream_dag.Load_user_dim_table scheduled__2023-01-01T10:00:00+00:00 [queued]>
[2025-07-24T16:57:15.393+0000] {taskinstance.py:2170} INFO - Starting attempt 1 of 4
[2025-07-24T16:57:15.665+0000] {taskinstance.py:2191} INFO - Executing <Task(PythonOperator): Load_user_dim_table> on 2023-01-01 10:00:00+00:00
[2025-07-24T16:57:15.693+0000] {standard_task_runner.py:60} INFO - Started process 453 to run task
[2025-07-24T16:57:15.705+0000] {standard_task_runner.py:87} INFO - Running: ['***', 'tasks', 'run', 'tune_stream_dag', 'Load_user_dim_table', 'scheduled__2023-01-01T10:00:00+00:00', '--job-id', '1838', '--raw', '--subdir', 'DAGS_FOLDER/etl_pipeline.py', '--cfg-path', '/tmp/tmpfyba1kbt']
[2025-07-24T16:57:15.717+0000] {standard_task_runner.py:88} INFO - Job 1838: Subtask Load_user_dim_table
[2025-07-24T16:57:16.218+0000] {task_command.py:423} INFO - Running <TaskInstance: tune_stream_dag.Load_user_dim_table scheduled__2023-01-01T10:00:00+00:00 [running]> on host 5def55d2a1b5
[2025-07-24T16:57:16.671+0000] {taskinstance.py:2480} INFO - Exporting env vars: AIRFLOW_CTX_DAG_OWNER='genz-legend' AIRFLOW_CTX_DAG_ID='tune_stream_dag' AIRFLOW_CTX_TASK_ID='Load_user_dim_table' AIRFLOW_CTX_EXECUTION_DATE='2023-01-01T10:00:00+00:00' AIRFLOW_CTX_TRY_NUMBER='1' AIRFLOW_CTX_DAG_RUN_ID='scheduled__2023-01-01T10:00:00+00:00'
[2025-07-24T16:57:16.813+0000] {taskinstance.py:2698} ERROR - Task failed with exception
Traceback (most recent call last):
  File "/home/airflow/.local/lib/python3.8/site-packages/airflow/models/taskinstance.py", line 433, in _execute_task
    result = execute_callable(context=context, **execute_callable_kwargs)
  File "/home/airflow/.local/lib/python3.8/site-packages/airflow/operators/python.py", line 199, in execute
    return_value = self.execute_callable()
  File "/home/airflow/.local/lib/python3.8/site-packages/airflow/operators/python.py", line 216, in execute_callable
    return self.python_callable(*self.op_args, **self.op_kwargs)
  File "/opt/airflow/dags/etl_pipeline.py", line 179, in <lambda>
    python_callable=lambda: load_table(SqlQueries.user_table_insert, 'users'),
  File "/opt/airflow/dags/etl_pipeline.py", line 132, in load_table
    cur.execute(f"INSERT INTO {table} {query}")
psycopg2.errors.UniqueViolation: duplicate key value violates unique constraint "users_pkey"
DETAIL:  Key (userid)=(88) already exists.

[2025-07-24T16:57:16.932+0000] {taskinstance.py:1138} INFO - Marking task as UP_FOR_RETRY. dag_id=tune_stream_dag, task_id=Load_user_dim_table, execution_date=20230101T100000, start_date=20250724T165715, end_date=20250724T165716
[2025-07-24T16:57:17.041+0000] {standard_task_runner.py:107} ERROR - Failed to execute job 1838 for task Load_user_dim_table (duplicate key value violates unique constraint "users_pkey"
DETAIL:  Key (userid)=(88) already exists.
; 453)
[2025-07-24T16:57:17.126+0000] {local_task_job_runner.py:234} INFO - Task exited with return code 1
[2025-07-24T16:57:17.171+0000] {taskinstance.py:3280} INFO - 0 downstream tasks scheduled from follow-on schedule check
