[2025-07-24T16:47:19.150+0000] {taskinstance.py:1956} INFO - Dependencies all met for dep_context=non-requeueable deps ti=<TaskInstance: tune_stream_dag.Load_time_dim_table scheduled__2023-01-01T20:00:00+00:00 [queued]>
[2025-07-24T16:47:19.165+0000] {taskinstance.py:1956} INFO - Dependencies all met for dep_context=requeueable deps ti=<TaskInstance: tune_stream_dag.Load_time_dim_table scheduled__2023-01-01T20:00:00+00:00 [queued]>
[2025-07-24T16:47:19.167+0000] {taskinstance.py:2170} INFO - Starting attempt 3 of 4
[2025-07-24T16:47:19.188+0000] {taskinstance.py:2191} INFO - Executing <Task(PythonOperator): Load_time_dim_table> on 2023-01-01 20:00:00+00:00
[2025-07-24T16:47:19.199+0000] {standard_task_runner.py:60} INFO - Started process 314 to run task
[2025-07-24T16:47:19.208+0000] {standard_task_runner.py:87} INFO - Running: ['***', 'tasks', 'run', 'tune_stream_dag', 'Load_time_dim_table', 'scheduled__2023-01-01T20:00:00+00:00', '--job-id', '1727', '--raw', '--subdir', 'DAGS_FOLDER/etl_pipeline.py', '--cfg-path', '/tmp/tmp3ghw_w1x']
[2025-07-24T16:47:19.213+0000] {standard_task_runner.py:88} INFO - Job 1727: Subtask Load_time_dim_table
[2025-07-24T16:47:19.328+0000] {task_command.py:423} INFO - Running <TaskInstance: tune_stream_dag.Load_time_dim_table scheduled__2023-01-01T20:00:00+00:00 [running]> on host 5def55d2a1b5
[2025-07-24T16:47:19.446+0000] {taskinstance.py:2480} INFO - Exporting env vars: AIRFLOW_CTX_DAG_OWNER='genz-legend' AIRFLOW_CTX_DAG_ID='tune_stream_dag' AIRFLOW_CTX_TASK_ID='Load_time_dim_table' AIRFLOW_CTX_EXECUTION_DATE='2023-01-01T20:00:00+00:00' AIRFLOW_CTX_TRY_NUMBER='3' AIRFLOW_CTX_DAG_RUN_ID='scheduled__2023-01-01T20:00:00+00:00'
[2025-07-24T16:47:19.457+0000] {taskinstance.py:2698} ERROR - Task failed with exception
Traceback (most recent call last):
  File "/home/airflow/.local/lib/python3.8/site-packages/airflow/models/taskinstance.py", line 433, in _execute_task
    result = execute_callable(context=context, **execute_callable_kwargs)
  File "/home/airflow/.local/lib/python3.8/site-packages/airflow/operators/python.py", line 199, in execute
    return_value = self.execute_callable()
  File "/home/airflow/.local/lib/python3.8/site-packages/airflow/operators/python.py", line 216, in execute_callable
    return self.python_callable(*self.op_args, **self.op_kwargs)
  File "/opt/airflow/dags/etl_pipeline.py", line 197, in <lambda>
    python_callable=lambda: load_table(SqlQueries.time_table_insert, 'time'),
  File "/opt/airflow/dags/etl_pipeline.py", line 131, in load_table
    cur.execute(f"TRUNCATE TABLE {table}")
psycopg2.errors.UndefinedTable: relation "time" does not exist

[2025-07-24T16:47:19.475+0000] {taskinstance.py:1138} INFO - Marking task as UP_FOR_RETRY. dag_id=tune_stream_dag, task_id=Load_time_dim_table, execution_date=20230101T200000, start_date=20250724T164719, end_date=20250724T164719
[2025-07-24T16:47:19.496+0000] {standard_task_runner.py:107} ERROR - Failed to execute job 1727 for task Load_time_dim_table (relation "time" does not exist
; 314)
[2025-07-24T16:47:19.543+0000] {local_task_job_runner.py:234} INFO - Task exited with return code 1
[2025-07-24T16:47:19.586+0000] {taskinstance.py:3280} INFO - 0 downstream tasks scheduled from follow-on schedule check
