[2025-07-24T15:21:28.390+0000] {taskinstance.py:1956} INFO - Dependencies all met for dep_context=non-requeueable deps ti=<TaskInstance: tune_stream_dag.Load_songplays_fact_table scheduled__2023-01-04T23:00:00+00:00 [queued]>
[2025-07-24T15:21:28.398+0000] {taskinstance.py:1956} INFO - Dependencies all met for dep_context=requeueable deps ti=<TaskInstance: tune_stream_dag.Load_songplays_fact_table scheduled__2023-01-04T23:00:00+00:00 [queued]>
[2025-07-24T15:21:28.399+0000] {taskinstance.py:2170} INFO - Starting attempt 2 of 4
[2025-07-24T15:21:29.119+0000] {taskinstance.py:2191} INFO - Executing <Task(PythonOperator): Load_songplays_fact_table> on 2023-01-04 23:00:00+00:00
[2025-07-24T15:21:29.138+0000] {standard_task_runner.py:60} INFO - Started process 746 to run task
[2025-07-24T15:21:29.141+0000] {standard_task_runner.py:87} INFO - Running: ['***', 'tasks', 'run', 'tune_stream_dag', 'Load_songplays_fact_table', 'scheduled__2023-01-04T23:00:00+00:00', '--job-id', '848', '--raw', '--subdir', 'DAGS_FOLDER/etl_pipeline.py', '--cfg-path', '/tmp/tmpewwk5shg']
[2025-07-24T15:21:29.146+0000] {standard_task_runner.py:88} INFO - Job 848: Subtask Load_songplays_fact_table
[2025-07-24T15:21:31.553+0000] {task_command.py:423} INFO - Running <TaskInstance: tune_stream_dag.Load_songplays_fact_table scheduled__2023-01-04T23:00:00+00:00 [running]> on host c53547d84df1
[2025-07-24T15:21:33.385+0000] {taskinstance.py:2480} INFO - Exporting env vars: AIRFLOW_CTX_DAG_OWNER='genz-legend' AIRFLOW_CTX_DAG_ID='tune_stream_dag' AIRFLOW_CTX_TASK_ID='Load_songplays_fact_table' AIRFLOW_CTX_EXECUTION_DATE='2023-01-04T23:00:00+00:00' AIRFLOW_CTX_TRY_NUMBER='2' AIRFLOW_CTX_DAG_RUN_ID='scheduled__2023-01-04T23:00:00+00:00'
[2025-07-24T15:21:33.419+0000] {taskinstance.py:2698} ERROR - Task failed with exception
Traceback (most recent call last):
  File "/home/airflow/.local/lib/python3.8/site-packages/airflow/models/taskinstance.py", line 433, in _execute_task
    result = execute_callable(context=context, **execute_callable_kwargs)
  File "/home/airflow/.local/lib/python3.8/site-packages/airflow/operators/python.py", line 199, in execute
    return_value = self.execute_callable()
  File "/home/airflow/.local/lib/python3.8/site-packages/airflow/operators/python.py", line 216, in execute_callable
    return self.python_callable(*self.op_args, **self.op_kwargs)
  File "/opt/airflow/dags/etl_pipeline.py", line 173, in <lambda>
    python_callable=lambda: load_table(SqlQueries.songplay_table_insert, 'songplays'),
  File "/opt/airflow/dags/etl_pipeline.py", line 132, in load_table
    cur.execute(f"INSERT INTO {table} {query}")
psycopg2.errors.UniqueViolation: duplicate key value violates unique constraint "songplays_pkey"
DETAIL:  Key (playid)=(94ee173577ff1ecb930371ff51f3a82b) already exists.

[2025-07-24T15:21:33.432+0000] {taskinstance.py:1138} INFO - Marking task as UP_FOR_RETRY. dag_id=tune_stream_dag, task_id=Load_songplays_fact_table, execution_date=20230104T230000, start_date=20250724T152128, end_date=20250724T152133
[2025-07-24T15:21:33.636+0000] {standard_task_runner.py:107} ERROR - Failed to execute job 848 for task Load_songplays_fact_table (duplicate key value violates unique constraint "songplays_pkey"
DETAIL:  Key (playid)=(94ee173577ff1ecb930371ff51f3a82b) already exists.
; 746)
[2025-07-24T15:21:33.688+0000] {local_task_job_runner.py:234} INFO - Task exited with return code 1
[2025-07-24T15:22:03.729+0000] {taskinstance.py:3280} INFO - 0 downstream tasks scheduled from follow-on schedule check
