[2025-07-22T10:23:26.005+0000] {taskinstance.py:1956} INFO - Dependencies all met for dep_context=non-requeueable deps ti=<TaskInstance: tune_stream_dag.Stage_events manual__2025-07-22T10:16:36.898393+00:00 [queued]>
[2025-07-22T10:23:26.014+0000] {taskinstance.py:1956} INFO - Dependencies all met for dep_context=requeueable deps ti=<TaskInstance: tune_stream_dag.Stage_events manual__2025-07-22T10:16:36.898393+00:00 [queued]>
[2025-07-22T10:23:26.015+0000] {taskinstance.py:2170} INFO - Starting attempt 2 of 4
[2025-07-22T10:23:26.032+0000] {taskinstance.py:2191} INFO - Executing <Task(PythonOperator): Stage_events> on 2025-07-22 10:16:36.898393+00:00
[2025-07-22T10:23:26.043+0000] {standard_task_runner.py:60} INFO - Started process 191 to run task
[2025-07-22T10:23:26.047+0000] {standard_task_runner.py:87} INFO - Running: ['***', 'tasks', 'run', 'tune_stream_dag', 'Stage_events', 'manual__2025-07-22T10:16:36.898393+00:00', '--job-id', '220', '--raw', '--subdir', 'DAGS_FOLDER/etl_pipeline.py', '--cfg-path', '/tmp/tmpxdk2q3c1']
[2025-07-22T10:23:26.053+0000] {standard_task_runner.py:88} INFO - Job 220: Subtask Stage_events
[2025-07-22T10:23:26.146+0000] {task_command.py:423} INFO - Running <TaskInstance: tune_stream_dag.Stage_events manual__2025-07-22T10:16:36.898393+00:00 [running]> on host a2a13a541787
[2025-07-22T10:23:26.239+0000] {taskinstance.py:2480} INFO - Exporting env vars: AIRFLOW_CTX_DAG_OWNER='genz-legend' AIRFLOW_CTX_DAG_ID='tune_stream_dag' AIRFLOW_CTX_TASK_ID='Stage_events' AIRFLOW_CTX_EXECUTION_DATE='2025-07-22T10:16:36.898393+00:00' AIRFLOW_CTX_TRY_NUMBER='2' AIRFLOW_CTX_DAG_RUN_ID='manual__2025-07-22T10:16:36.898393+00:00'
[2025-07-22T10:23:26.260+0000] {taskinstance.py:2698} ERROR - Task failed with exception
Traceback (most recent call last):
  File "/home/airflow/.local/lib/python3.8/site-packages/airflow/models/taskinstance.py", line 433, in _execute_task
    result = execute_callable(context=context, **execute_callable_kwargs)
  File "/home/airflow/.local/lib/python3.8/site-packages/airflow/operators/python.py", line 199, in execute
    return_value = self.execute_callable()
  File "/home/airflow/.local/lib/python3.8/site-packages/airflow/operators/python.py", line 216, in execute_callable
    return self.python_callable(*self.op_args, **self.op_kwargs)
  File "/opt/airflow/dags/etl_pipeline.py", line 81, in stage_events
    cur.execute(insert_query, (
UnboundLocalError: local variable 'insert_query' referenced before assignment
[2025-07-22T10:23:26.288+0000] {taskinstance.py:1138} INFO - Marking task as UP_FOR_RETRY. dag_id=tune_stream_dag, task_id=Stage_events, execution_date=20250722T101636, start_date=20250722T102326, end_date=20250722T102326
[2025-07-22T10:23:26.308+0000] {standard_task_runner.py:107} ERROR - Failed to execute job 220 for task Stage_events (local variable 'insert_query' referenced before assignment; 191)
[2025-07-22T10:23:26.344+0000] {local_task_job_runner.py:234} INFO - Task exited with return code 1
[2025-07-22T10:23:26.423+0000] {taskinstance.py:3280} INFO - 0 downstream tasks scheduled from follow-on schedule check
