[2025-07-24T16:05:03.817+0000] {taskinstance.py:1956} INFO - Dependencies all met for dep_context=non-requeueable deps ti=<TaskInstance: tune_stream_dag.Load_user_dim_table scheduled__2023-01-02T00:00:00+00:00 [queued]>
[2025-07-24T16:05:03.833+0000] {taskinstance.py:1956} INFO - Dependencies all met for dep_context=requeueable deps ti=<TaskInstance: tune_stream_dag.Load_user_dim_table scheduled__2023-01-02T00:00:00+00:00 [queued]>
[2025-07-24T16:05:03.835+0000] {taskinstance.py:2170} INFO - Starting attempt 2 of 4
[2025-07-24T16:05:03.857+0000] {taskinstance.py:2191} INFO - Executing <Task(PythonOperator): Load_user_dim_table> on 2023-01-02 00:00:00+00:00
[2025-07-24T16:05:03.868+0000] {standard_task_runner.py:60} INFO - Started process 1733 to run task
[2025-07-24T16:05:03.873+0000] {standard_task_runner.py:87} INFO - Running: ['***', 'tasks', 'run', 'tune_stream_dag', 'Load_user_dim_table', 'scheduled__2023-01-02T00:00:00+00:00', '--job-id', '1332', '--raw', '--subdir', 'DAGS_FOLDER/etl_pipeline.py', '--cfg-path', '/tmp/tmpxk68ma9z']
[2025-07-24T16:05:03.879+0000] {standard_task_runner.py:88} INFO - Job 1332: Subtask Load_user_dim_table
[2025-07-24T16:05:04.019+0000] {task_command.py:423} INFO - Running <TaskInstance: tune_stream_dag.Load_user_dim_table scheduled__2023-01-02T00:00:00+00:00 [running]> on host c53547d84df1
[2025-07-24T16:05:04.150+0000] {taskinstance.py:2480} INFO - Exporting env vars: AIRFLOW_CTX_DAG_OWNER='genz-legend' AIRFLOW_CTX_DAG_ID='tune_stream_dag' AIRFLOW_CTX_TASK_ID='Load_user_dim_table' AIRFLOW_CTX_EXECUTION_DATE='2023-01-02T00:00:00+00:00' AIRFLOW_CTX_TRY_NUMBER='2' AIRFLOW_CTX_DAG_RUN_ID='scheduled__2023-01-02T00:00:00+00:00'
[2025-07-24T16:05:04.166+0000] {taskinstance.py:2698} ERROR - Task failed with exception
Traceback (most recent call last):
  File "/home/airflow/.local/lib/python3.8/site-packages/airflow/models/taskinstance.py", line 433, in _execute_task
    result = execute_callable(context=context, **execute_callable_kwargs)
  File "/home/airflow/.local/lib/python3.8/site-packages/airflow/operators/python.py", line 199, in execute
    return_value = self.execute_callable()
  File "/home/airflow/.local/lib/python3.8/site-packages/airflow/operators/python.py", line 216, in execute_callable
    return self.python_callable(*self.op_args, **self.op_kwargs)
  File "/opt/airflow/dags/etl_pipeline.py", line 179, in <lambda>
    python_callable=lambda: load_table(SqlQueries.user_table_insert, 'users'),
  File "/opt/airflow/dags/etl_pipeline.py", line 132, in load_table
    cur.execute(f"INSERT INTO {table} {query}")
psycopg2.errors.UniqueViolation: duplicate key value violates unique constraint "users_pkey"
DETAIL:  Key (userid)=(88) already exists.

[2025-07-24T16:05:04.181+0000] {taskinstance.py:1138} INFO - Marking task as UP_FOR_RETRY. dag_id=tune_stream_dag, task_id=Load_user_dim_table, execution_date=20230102T000000, start_date=20250724T160503, end_date=20250724T160504
[2025-07-24T16:05:04.194+0000] {standard_task_runner.py:107} ERROR - Failed to execute job 1332 for task Load_user_dim_table (duplicate key value violates unique constraint "users_pkey"
DETAIL:  Key (userid)=(88) already exists.
; 1733)
[2025-07-24T16:05:04.209+0000] {local_task_job_runner.py:234} INFO - Task exited with return code 1
[2025-07-24T16:05:04.289+0000] {taskinstance.py:3280} INFO - 0 downstream tasks scheduled from follow-on schedule check
[2025-07-24T16:42:21.399+0000] {taskinstance.py:1956} INFO - Dependencies all met for dep_context=non-requeueable deps ti=<TaskInstance: tune_stream_dag.Load_user_dim_table scheduled__2023-01-02T00:00:00+00:00 [queued]>
[2025-07-24T16:42:21.454+0000] {taskinstance.py:1956} INFO - Dependencies all met for dep_context=requeueable deps ti=<TaskInstance: tune_stream_dag.Load_user_dim_table scheduled__2023-01-02T00:00:00+00:00 [queued]>
[2025-07-24T16:42:21.455+0000] {taskinstance.py:2170} INFO - Starting attempt 2 of 4
[2025-07-24T16:42:21.492+0000] {taskinstance.py:2191} INFO - Executing <Task(PythonOperator): Load_user_dim_table> on 2023-01-02 00:00:00+00:00
[2025-07-24T16:42:21.573+0000] {standard_task_runner.py:60} INFO - Started process 171 to run task
[2025-07-24T16:42:21.636+0000] {standard_task_runner.py:87} INFO - Running: ['***', 'tasks', 'run', 'tune_stream_dag', 'Load_user_dim_table', 'scheduled__2023-01-02T00:00:00+00:00', '--job-id', '1704', '--raw', '--subdir', 'DAGS_FOLDER/etl_pipeline.py', '--cfg-path', '/tmp/tmpza3b8ww8']
[2025-07-24T16:42:21.656+0000] {standard_task_runner.py:88} INFO - Job 1704: Subtask Load_user_dim_table
[2025-07-24T16:42:22.012+0000] {task_command.py:423} INFO - Running <TaskInstance: tune_stream_dag.Load_user_dim_table scheduled__2023-01-02T00:00:00+00:00 [running]> on host 5def55d2a1b5
[2025-07-24T16:42:22.668+0000] {taskinstance.py:2480} INFO - Exporting env vars: AIRFLOW_CTX_DAG_OWNER='genz-legend' AIRFLOW_CTX_DAG_ID='tune_stream_dag' AIRFLOW_CTX_TASK_ID='Load_user_dim_table' AIRFLOW_CTX_EXECUTION_DATE='2023-01-02T00:00:00+00:00' AIRFLOW_CTX_TRY_NUMBER='2' AIRFLOW_CTX_DAG_RUN_ID='scheduled__2023-01-02T00:00:00+00:00'
[2025-07-24T16:42:23.050+0000] {taskinstance.py:2698} ERROR - Task failed with exception
Traceback (most recent call last):
  File "/home/airflow/.local/lib/python3.8/site-packages/airflow/models/taskinstance.py", line 433, in _execute_task
    result = execute_callable(context=context, **execute_callable_kwargs)
  File "/home/airflow/.local/lib/python3.8/site-packages/airflow/operators/python.py", line 199, in execute
    return_value = self.execute_callable()
  File "/home/airflow/.local/lib/python3.8/site-packages/airflow/operators/python.py", line 216, in execute_callable
    return self.python_callable(*self.op_args, **self.op_kwargs)
  File "/opt/airflow/dags/etl_pipeline.py", line 179, in <lambda>
    python_callable=lambda: load_table(SqlQueries.user_table_insert, 'users'),
  File "/opt/airflow/dags/etl_pipeline.py", line 132, in load_table
    cur.execute(f"INSERT INTO {table} {query}")
psycopg2.errors.UniqueViolation: duplicate key value violates unique constraint "users_pkey"
DETAIL:  Key (userid)=(88) already exists.

[2025-07-24T16:42:23.217+0000] {taskinstance.py:1138} INFO - Marking task as UP_FOR_RETRY. dag_id=tune_stream_dag, task_id=Load_user_dim_table, execution_date=20230102T000000, start_date=20250724T164221, end_date=20250724T164223
[2025-07-24T16:42:23.336+0000] {standard_task_runner.py:107} ERROR - Failed to execute job 1704 for task Load_user_dim_table (duplicate key value violates unique constraint "users_pkey"
DETAIL:  Key (userid)=(88) already exists.
; 171)
[2025-07-24T16:42:23.399+0000] {local_task_job_runner.py:234} INFO - Task exited with return code 1
[2025-07-24T16:42:23.511+0000] {taskinstance.py:3280} INFO - 0 downstream tasks scheduled from follow-on schedule check
[2025-07-24T17:19:20.889+0000] {taskinstance.py:1956} INFO - Dependencies all met for dep_context=non-requeueable deps ti=<TaskInstance: tune_stream_dag.Load_user_dim_table scheduled__2023-01-02T00:00:00+00:00 [queued]>
[2025-07-24T17:19:21.034+0000] {taskinstance.py:1956} INFO - Dependencies all met for dep_context=requeueable deps ti=<TaskInstance: tune_stream_dag.Load_user_dim_table scheduled__2023-01-02T00:00:00+00:00 [queued]>
[2025-07-24T17:19:21.178+0000] {taskinstance.py:2170} INFO - Starting attempt 2 of 4
[2025-07-24T17:19:23.707+0000] {taskinstance.py:2191} INFO - Executing <Task(PythonOperator): Load_user_dim_table> on 2023-01-02 00:00:00+00:00
[2025-07-24T17:19:23.772+0000] {standard_task_runner.py:60} INFO - Started process 1814 to run task
[2025-07-24T17:19:23.779+0000] {standard_task_runner.py:87} INFO - Running: ['***', 'tasks', 'run', 'tune_stream_dag', 'Load_user_dim_table', 'scheduled__2023-01-02T00:00:00+00:00', '--job-id', '2181', '--raw', '--subdir', 'DAGS_FOLDER/etl_pipeline.py', '--cfg-path', '/tmp/tmpybji86hh']
[2025-07-24T17:19:23.784+0000] {standard_task_runner.py:88} INFO - Job 2181: Subtask Load_user_dim_table
[2025-07-24T17:19:29.968+0000] {task_command.py:423} INFO - Running <TaskInstance: tune_stream_dag.Load_user_dim_table scheduled__2023-01-02T00:00:00+00:00 [running]> on host 5def55d2a1b5
[2025-07-24T17:20:16.083+0000] {taskinstance.py:2480} INFO - Exporting env vars: AIRFLOW_CTX_DAG_OWNER='genz-legend' AIRFLOW_CTX_DAG_ID='tune_stream_dag' AIRFLOW_CTX_TASK_ID='Load_user_dim_table' AIRFLOW_CTX_EXECUTION_DATE='2023-01-02T00:00:00+00:00' AIRFLOW_CTX_TRY_NUMBER='2' AIRFLOW_CTX_DAG_RUN_ID='scheduled__2023-01-02T00:00:00+00:00'
[2025-07-24T17:20:37.756+0000] {python.py:201} INFO - Done. Returned value was: None
[2025-07-24T17:20:37.779+0000] {taskinstance.py:1138} INFO - Marking task as SUCCESS. dag_id=tune_stream_dag, task_id=Load_user_dim_table, execution_date=20230102T000000, start_date=20250724T171921, end_date=20250724T172037
[2025-07-24T17:20:38.143+0000] {local_task_job_runner.py:234} INFO - Task exited with return code 0
[2025-07-24T17:20:38.720+0000] {taskinstance.py:3280} INFO - 0 downstream tasks scheduled from follow-on schedule check
