[2025-07-24T15:54:09.118+0000] {taskinstance.py:1956} INFO - Dependencies all met for dep_context=non-requeueable deps ti=<TaskInstance: tune_stream_dag.Load_time_dim_table scheduled__2023-01-01T08:00:00+00:00 [queued]>
[2025-07-24T15:54:09.128+0000] {taskinstance.py:1956} INFO - Dependencies all met for dep_context=requeueable deps ti=<TaskInstance: tune_stream_dag.Load_time_dim_table scheduled__2023-01-01T08:00:00+00:00 [queued]>
[2025-07-24T15:54:09.129+0000] {taskinstance.py:2170} INFO - Starting attempt 3 of 4
[2025-07-24T15:54:09.141+0000] {taskinstance.py:2191} INFO - Executing <Task(PythonOperator): Load_time_dim_table> on 2023-01-01 08:00:00+00:00
[2025-07-24T15:54:09.147+0000] {standard_task_runner.py:60} INFO - Started process 1131 to run task
[2025-07-24T15:54:09.150+0000] {standard_task_runner.py:87} INFO - Running: ['***', 'tasks', 'run', 'tune_stream_dag', 'Load_time_dim_table', 'scheduled__2023-01-01T08:00:00+00:00', '--job-id', '1186', '--raw', '--subdir', 'DAGS_FOLDER/etl_pipeline.py', '--cfg-path', '/tmp/tmpirr1kbrr']
[2025-07-24T15:54:09.153+0000] {standard_task_runner.py:88} INFO - Job 1186: Subtask Load_time_dim_table
[2025-07-24T15:54:09.219+0000] {task_command.py:423} INFO - Running <TaskInstance: tune_stream_dag.Load_time_dim_table scheduled__2023-01-01T08:00:00+00:00 [running]> on host c53547d84df1
[2025-07-24T15:54:09.289+0000] {taskinstance.py:2480} INFO - Exporting env vars: AIRFLOW_CTX_DAG_OWNER='genz-legend' AIRFLOW_CTX_DAG_ID='tune_stream_dag' AIRFLOW_CTX_TASK_ID='Load_time_dim_table' AIRFLOW_CTX_EXECUTION_DATE='2023-01-01T08:00:00+00:00' AIRFLOW_CTX_TRY_NUMBER='3' AIRFLOW_CTX_DAG_RUN_ID='scheduled__2023-01-01T08:00:00+00:00'
[2025-07-24T15:54:09.298+0000] {taskinstance.py:2698} ERROR - Task failed with exception
Traceback (most recent call last):
  File "/home/airflow/.local/lib/python3.8/site-packages/airflow/models/taskinstance.py", line 433, in _execute_task
    result = execute_callable(context=context, **execute_callable_kwargs)
  File "/home/airflow/.local/lib/python3.8/site-packages/airflow/operators/python.py", line 199, in execute
    return_value = self.execute_callable()
  File "/home/airflow/.local/lib/python3.8/site-packages/airflow/operators/python.py", line 216, in execute_callable
    return self.python_callable(*self.op_args, **self.op_kwargs)
  File "/opt/airflow/dags/etl_pipeline.py", line 197, in <lambda>
    python_callable=lambda: load_table(SqlQueries.time_table_insert, 'time'),
  File "/opt/airflow/dags/etl_pipeline.py", line 132, in load_table
    cur.execute(f"INSERT INTO {table} {query}")
psycopg2.errors.InvalidParameterValue: timestamp units "dayofweek" not recognized

[2025-07-24T15:54:09.309+0000] {taskinstance.py:1138} INFO - Marking task as UP_FOR_RETRY. dag_id=tune_stream_dag, task_id=Load_time_dim_table, execution_date=20230101T080000, start_date=20250724T155409, end_date=20250724T155409
[2025-07-24T15:54:09.323+0000] {standard_task_runner.py:107} ERROR - Failed to execute job 1186 for task Load_time_dim_table (timestamp units "dayofweek" not recognized
; 1131)
[2025-07-24T15:54:09.364+0000] {local_task_job_runner.py:234} INFO - Task exited with return code 1
[2025-07-24T15:54:09.389+0000] {taskinstance.py:3280} INFO - 0 downstream tasks scheduled from follow-on schedule check
[2025-07-24T16:28:09.109+0000] {taskinstance.py:1956} INFO - Dependencies all met for dep_context=non-requeueable deps ti=<TaskInstance: tune_stream_dag.Load_time_dim_table scheduled__2023-01-01T08:00:00+00:00 [queued]>
[2025-07-24T16:28:09.118+0000] {taskinstance.py:1956} INFO - Dependencies all met for dep_context=requeueable deps ti=<TaskInstance: tune_stream_dag.Load_time_dim_table scheduled__2023-01-01T08:00:00+00:00 [queued]>
[2025-07-24T16:28:09.119+0000] {taskinstance.py:2170} INFO - Starting attempt 3 of 4
[2025-07-24T16:28:09.131+0000] {taskinstance.py:2191} INFO - Executing <Task(PythonOperator): Load_time_dim_table> on 2023-01-01 08:00:00+00:00
[2025-07-24T16:28:09.136+0000] {standard_task_runner.py:60} INFO - Started process 835 to run task
[2025-07-24T16:28:09.140+0000] {standard_task_runner.py:87} INFO - Running: ['***', 'tasks', 'run', 'tune_stream_dag', 'Load_time_dim_table', 'scheduled__2023-01-01T08:00:00+00:00', '--job-id', '1520', '--raw', '--subdir', 'DAGS_FOLDER/etl_pipeline.py', '--cfg-path', '/tmp/tmp83rih_6n']
[2025-07-24T16:28:09.143+0000] {standard_task_runner.py:88} INFO - Job 1520: Subtask Load_time_dim_table
[2025-07-24T16:28:09.199+0000] {task_command.py:423} INFO - Running <TaskInstance: tune_stream_dag.Load_time_dim_table scheduled__2023-01-01T08:00:00+00:00 [running]> on host c53547d84df1
[2025-07-24T16:28:09.262+0000] {taskinstance.py:2480} INFO - Exporting env vars: AIRFLOW_CTX_DAG_OWNER='genz-legend' AIRFLOW_CTX_DAG_ID='tune_stream_dag' AIRFLOW_CTX_TASK_ID='Load_time_dim_table' AIRFLOW_CTX_EXECUTION_DATE='2023-01-01T08:00:00+00:00' AIRFLOW_CTX_TRY_NUMBER='3' AIRFLOW_CTX_DAG_RUN_ID='scheduled__2023-01-01T08:00:00+00:00'
[2025-07-24T16:28:09.286+0000] {taskinstance.py:2698} ERROR - Task failed with exception
Traceback (most recent call last):
  File "/home/airflow/.local/lib/python3.8/site-packages/airflow/models/taskinstance.py", line 433, in _execute_task
    result = execute_callable(context=context, **execute_callable_kwargs)
  File "/home/airflow/.local/lib/python3.8/site-packages/airflow/operators/python.py", line 199, in execute
    return_value = self.execute_callable()
  File "/home/airflow/.local/lib/python3.8/site-packages/airflow/operators/python.py", line 216, in execute_callable
    return self.python_callable(*self.op_args, **self.op_kwargs)
  File "/opt/airflow/dags/etl_pipeline.py", line 197, in <lambda>
    python_callable=lambda: load_table(SqlQueries.time_table_insert, 'time'),
  File "/opt/airflow/dags/etl_pipeline.py", line 132, in load_table
    cur.execute(f"INSERT INTO {table} {query}")
psycopg2.errors.UniqueViolation: duplicate key value violates unique constraint "time_pkey"
DETAIL:  Key (start_time)=(2018-11-14 04:53:36) already exists.

[2025-07-24T16:28:09.297+0000] {taskinstance.py:1138} INFO - Marking task as UP_FOR_RETRY. dag_id=tune_stream_dag, task_id=Load_time_dim_table, execution_date=20230101T080000, start_date=20250724T162809, end_date=20250724T162809
[2025-07-24T16:28:09.307+0000] {standard_task_runner.py:107} ERROR - Failed to execute job 1520 for task Load_time_dim_table (duplicate key value violates unique constraint "time_pkey"
DETAIL:  Key (start_time)=(2018-11-14 04:53:36) already exists.
; 835)
[2025-07-24T16:28:09.352+0000] {local_task_job_runner.py:234} INFO - Task exited with return code 1
[2025-07-24T16:28:09.382+0000] {taskinstance.py:3280} INFO - 0 downstream tasks scheduled from follow-on schedule check
[2025-07-24T17:07:24.634+0000] {taskinstance.py:1956} INFO - Dependencies all met for dep_context=non-requeueable deps ti=<TaskInstance: tune_stream_dag.Load_time_dim_table scheduled__2023-01-01T08:00:00+00:00 [queued]>
[2025-07-24T17:07:24.673+0000] {taskinstance.py:1956} INFO - Dependencies all met for dep_context=requeueable deps ti=<TaskInstance: tune_stream_dag.Load_time_dim_table scheduled__2023-01-01T08:00:00+00:00 [queued]>
[2025-07-24T17:07:24.676+0000] {taskinstance.py:2170} INFO - Starting attempt 3 of 4
[2025-07-24T17:07:24.707+0000] {taskinstance.py:2191} INFO - Executing <Task(PythonOperator): Load_time_dim_table> on 2023-01-01 08:00:00+00:00
[2025-07-24T17:07:24.740+0000] {standard_task_runner.py:60} INFO - Started process 810 to run task
[2025-07-24T17:07:24.791+0000] {standard_task_runner.py:87} INFO - Running: ['***', 'tasks', 'run', 'tune_stream_dag', 'Load_time_dim_table', 'scheduled__2023-01-01T08:00:00+00:00', '--job-id', '1908', '--raw', '--subdir', 'DAGS_FOLDER/etl_pipeline.py', '--cfg-path', '/tmp/tmpzkatbc7c']
[2025-07-24T17:07:24.820+0000] {standard_task_runner.py:88} INFO - Job 1908: Subtask Load_time_dim_table
[2025-07-24T17:07:25.121+0000] {task_command.py:423} INFO - Running <TaskInstance: tune_stream_dag.Load_time_dim_table scheduled__2023-01-01T08:00:00+00:00 [running]> on host 5def55d2a1b5
[2025-07-24T17:07:25.605+0000] {taskinstance.py:2480} INFO - Exporting env vars: AIRFLOW_CTX_DAG_OWNER='genz-legend' AIRFLOW_CTX_DAG_ID='tune_stream_dag' AIRFLOW_CTX_TASK_ID='Load_time_dim_table' AIRFLOW_CTX_EXECUTION_DATE='2023-01-01T08:00:00+00:00' AIRFLOW_CTX_TRY_NUMBER='3' AIRFLOW_CTX_DAG_RUN_ID='scheduled__2023-01-01T08:00:00+00:00'
[2025-07-24T17:07:25.759+0000] {taskinstance.py:2698} ERROR - Task failed with exception
Traceback (most recent call last):
  File "/home/airflow/.local/lib/python3.8/site-packages/airflow/models/taskinstance.py", line 433, in _execute_task
    result = execute_callable(context=context, **execute_callable_kwargs)
  File "/home/airflow/.local/lib/python3.8/site-packages/airflow/operators/python.py", line 199, in execute
    return_value = self.execute_callable()
  File "/home/airflow/.local/lib/python3.8/site-packages/airflow/operators/python.py", line 216, in execute_callable
    return self.python_callable(*self.op_args, **self.op_kwargs)
  File "/opt/airflow/dags/etl_pipeline.py", line 197, in <lambda>
    python_callable=lambda: load_table(SqlQueries.time_table_insert, 'time'),
  File "/opt/airflow/dags/etl_pipeline.py", line 132, in load_table
    cur.execute(f"INSERT INTO {table} {query}")
psycopg2.errors.UniqueViolation: duplicate key value violates unique constraint "time_pkey"
DETAIL:  Key (start_time)=(2018-11-14 04:53:36) already exists.

[2025-07-24T17:07:25.813+0000] {taskinstance.py:1138} INFO - Marking task as UP_FOR_RETRY. dag_id=tune_stream_dag, task_id=Load_time_dim_table, execution_date=20230101T080000, start_date=20250724T170724, end_date=20250724T170725
[2025-07-24T17:07:25.895+0000] {standard_task_runner.py:107} ERROR - Failed to execute job 1908 for task Load_time_dim_table (duplicate key value violates unique constraint "time_pkey"
DETAIL:  Key (start_time)=(2018-11-14 04:53:36) already exists.
; 810)
[2025-07-24T17:07:25.971+0000] {local_task_job_runner.py:234} INFO - Task exited with return code 1
[2025-07-24T17:07:26.870+0000] {taskinstance.py:3280} INFO - 0 downstream tasks scheduled from follow-on schedule check
