[2025-07-24T16:04:32.055+0000] {taskinstance.py:1956} INFO - Dependencies all met for dep_context=non-requeueable deps ti=<TaskInstance: tune_stream_dag.Load_user_dim_table scheduled__2023-01-02T03:00:00+00:00 [queued]>
[2025-07-24T16:04:32.069+0000] {taskinstance.py:1956} INFO - Dependencies all met for dep_context=requeueable deps ti=<TaskInstance: tune_stream_dag.Load_user_dim_table scheduled__2023-01-02T03:00:00+00:00 [queued]>
[2025-07-24T16:04:32.070+0000] {taskinstance.py:2170} INFO - Starting attempt 1 of 4
[2025-07-24T16:04:32.089+0000] {taskinstance.py:2191} INFO - Executing <Task(PythonOperator): Load_user_dim_table> on 2023-01-02 03:00:00+00:00
[2025-07-24T16:04:32.102+0000] {standard_task_runner.py:60} INFO - Started process 1613 to run task
[2025-07-24T16:04:32.109+0000] {standard_task_runner.py:87} INFO - Running: ['***', 'tasks', 'run', 'tune_stream_dag', 'Load_user_dim_table', 'scheduled__2023-01-02T03:00:00+00:00', '--job-id', '1294', '--raw', '--subdir', 'DAGS_FOLDER/etl_pipeline.py', '--cfg-path', '/tmp/tmpkv8nlxjt']
[2025-07-24T16:04:32.114+0000] {standard_task_runner.py:88} INFO - Job 1294: Subtask Load_user_dim_table
[2025-07-24T16:04:32.207+0000] {task_command.py:423} INFO - Running <TaskInstance: tune_stream_dag.Load_user_dim_table scheduled__2023-01-02T03:00:00+00:00 [running]> on host c53547d84df1
[2025-07-24T16:04:32.307+0000] {taskinstance.py:2480} INFO - Exporting env vars: AIRFLOW_CTX_DAG_OWNER='genz-legend' AIRFLOW_CTX_DAG_ID='tune_stream_dag' AIRFLOW_CTX_TASK_ID='Load_user_dim_table' AIRFLOW_CTX_EXECUTION_DATE='2023-01-02T03:00:00+00:00' AIRFLOW_CTX_TRY_NUMBER='1' AIRFLOW_CTX_DAG_RUN_ID='scheduled__2023-01-02T03:00:00+00:00'
[2025-07-24T16:04:32.325+0000] {taskinstance.py:2698} ERROR - Task failed with exception
Traceback (most recent call last):
  File "/home/airflow/.local/lib/python3.8/site-packages/airflow/models/taskinstance.py", line 433, in _execute_task
    result = execute_callable(context=context, **execute_callable_kwargs)
  File "/home/airflow/.local/lib/python3.8/site-packages/airflow/operators/python.py", line 199, in execute
    return_value = self.execute_callable()
  File "/home/airflow/.local/lib/python3.8/site-packages/airflow/operators/python.py", line 216, in execute_callable
    return self.python_callable(*self.op_args, **self.op_kwargs)
  File "/opt/airflow/dags/etl_pipeline.py", line 179, in <lambda>
    python_callable=lambda: load_table(SqlQueries.user_table_insert, 'users'),
  File "/opt/airflow/dags/etl_pipeline.py", line 132, in load_table
    cur.execute(f"INSERT INTO {table} {query}")
psycopg2.errors.UniqueViolation: duplicate key value violates unique constraint "users_pkey"
DETAIL:  Key (userid)=(88) already exists.

[2025-07-24T16:04:32.342+0000] {taskinstance.py:1138} INFO - Marking task as UP_FOR_RETRY. dag_id=tune_stream_dag, task_id=Load_user_dim_table, execution_date=20230102T030000, start_date=20250724T160432, end_date=20250724T160432
[2025-07-24T16:04:32.357+0000] {standard_task_runner.py:107} ERROR - Failed to execute job 1294 for task Load_user_dim_table (duplicate key value violates unique constraint "users_pkey"
DETAIL:  Key (userid)=(88) already exists.
; 1613)
[2025-07-24T16:04:32.402+0000] {local_task_job_runner.py:234} INFO - Task exited with return code 1
[2025-07-24T16:04:33.669+0000] {taskinstance.py:3280} INFO - 0 downstream tasks scheduled from follow-on schedule check
[2025-07-24T16:35:11.992+0000] {taskinstance.py:1956} INFO - Dependencies all met for dep_context=non-requeueable deps ti=<TaskInstance: tune_stream_dag.Load_user_dim_table scheduled__2023-01-02T03:00:00+00:00 [queued]>
[2025-07-24T16:35:12.089+0000] {taskinstance.py:1956} INFO - Dependencies all met for dep_context=requeueable deps ti=<TaskInstance: tune_stream_dag.Load_user_dim_table scheduled__2023-01-02T03:00:00+00:00 [queued]>
[2025-07-24T16:35:12.094+0000] {taskinstance.py:2170} INFO - Starting attempt 1 of 4
[2025-07-24T16:35:12.288+0000] {taskinstance.py:2191} INFO - Executing <Task(PythonOperator): Load_user_dim_table> on 2023-01-02 03:00:00+00:00
[2025-07-24T16:35:12.314+0000] {standard_task_runner.py:60} INFO - Started process 1373 to run task
[2025-07-24T16:35:12.326+0000] {standard_task_runner.py:87} INFO - Running: ['***', 'tasks', 'run', 'tune_stream_dag', 'Load_user_dim_table', 'scheduled__2023-01-02T03:00:00+00:00', '--job-id', '1659', '--raw', '--subdir', 'DAGS_FOLDER/etl_pipeline.py', '--cfg-path', '/tmp/tmpz1mrf8ol']
[2025-07-24T16:35:12.401+0000] {standard_task_runner.py:88} INFO - Job 1659: Subtask Load_user_dim_table
[2025-07-24T16:35:12.749+0000] {task_command.py:423} INFO - Running <TaskInstance: tune_stream_dag.Load_user_dim_table scheduled__2023-01-02T03:00:00+00:00 [running]> on host c53547d84df1
[2025-07-24T16:35:13.123+0000] {taskinstance.py:2480} INFO - Exporting env vars: AIRFLOW_CTX_DAG_OWNER='genz-legend' AIRFLOW_CTX_DAG_ID='tune_stream_dag' AIRFLOW_CTX_TASK_ID='Load_user_dim_table' AIRFLOW_CTX_EXECUTION_DATE='2023-01-02T03:00:00+00:00' AIRFLOW_CTX_TRY_NUMBER='1' AIRFLOW_CTX_DAG_RUN_ID='scheduled__2023-01-02T03:00:00+00:00'
[2025-07-24T16:35:14.080+0000] {taskinstance.py:2698} ERROR - Task failed with exception
Traceback (most recent call last):
  File "/home/airflow/.local/lib/python3.8/site-packages/airflow/models/taskinstance.py", line 433, in _execute_task
    result = execute_callable(context=context, **execute_callable_kwargs)
  File "/home/airflow/.local/lib/python3.8/site-packages/airflow/operators/python.py", line 199, in execute
    return_value = self.execute_callable()
  File "/home/airflow/.local/lib/python3.8/site-packages/airflow/operators/python.py", line 216, in execute_callable
    return self.python_callable(*self.op_args, **self.op_kwargs)
  File "/opt/airflow/dags/etl_pipeline.py", line 179, in <lambda>
    python_callable=lambda: load_table(SqlQueries.user_table_insert, 'users'),
  File "/opt/airflow/dags/etl_pipeline.py", line 132, in load_table
    cur.execute(f"INSERT INTO {table} {query}")
psycopg2.errors.UniqueViolation: duplicate key value violates unique constraint "users_pkey"
DETAIL:  Key (userid)=(88) already exists.

[2025-07-24T16:35:14.107+0000] {taskinstance.py:1138} INFO - Marking task as UP_FOR_RETRY. dag_id=tune_stream_dag, task_id=Load_user_dim_table, execution_date=20230102T030000, start_date=20250724T163512, end_date=20250724T163514
[2025-07-24T16:35:15.061+0000] {standard_task_runner.py:107} ERROR - Failed to execute job 1659 for task Load_user_dim_table (duplicate key value violates unique constraint "users_pkey"
DETAIL:  Key (userid)=(88) already exists.
; 1373)
[2025-07-24T16:35:15.106+0000] {local_task_job_runner.py:234} INFO - Task exited with return code 1
[2025-07-24T16:35:15.555+0000] {taskinstance.py:3280} INFO - 0 downstream tasks scheduled from follow-on schedule check
[2025-07-24T17:14:07.486+0000] {taskinstance.py:1956} INFO - Dependencies all met for dep_context=non-requeueable deps ti=<TaskInstance: tune_stream_dag.Load_user_dim_table scheduled__2023-01-02T03:00:00+00:00 [queued]>
[2025-07-24T17:14:07.564+0000] {taskinstance.py:1956} INFO - Dependencies all met for dep_context=requeueable deps ti=<TaskInstance: tune_stream_dag.Load_user_dim_table scheduled__2023-01-02T03:00:00+00:00 [queued]>
[2025-07-24T17:14:07.350+0000] {taskinstance.py:2170} INFO - Starting attempt 1 of 4
[2025-07-24T17:14:07.467+0000] {taskinstance.py:2191} INFO - Executing <Task(PythonOperator): Load_user_dim_table> on 2023-01-02 03:00:00+00:00
[2025-07-24T17:14:07.504+0000] {standard_task_runner.py:60} INFO - Started process 1349 to run task
[2025-07-24T17:14:07.543+0000] {standard_task_runner.py:87} INFO - Running: ['***', 'tasks', 'run', 'tune_stream_dag', 'Load_user_dim_table', 'scheduled__2023-01-02T03:00:00+00:00', '--job-id', '2053', '--raw', '--subdir', 'DAGS_FOLDER/etl_pipeline.py', '--cfg-path', '/tmp/tmp5urqu8y0']
[2025-07-24T17:14:07.569+0000] {standard_task_runner.py:88} INFO - Job 2053: Subtask Load_user_dim_table
[2025-07-24T17:14:07.840+0000] {task_command.py:423} INFO - Running <TaskInstance: tune_stream_dag.Load_user_dim_table scheduled__2023-01-02T03:00:00+00:00 [running]> on host 5def55d2a1b5
[2025-07-24T17:14:08.300+0000] {taskinstance.py:2480} INFO - Exporting env vars: AIRFLOW_CTX_DAG_OWNER='genz-legend' AIRFLOW_CTX_DAG_ID='tune_stream_dag' AIRFLOW_CTX_TASK_ID='Load_user_dim_table' AIRFLOW_CTX_EXECUTION_DATE='2023-01-02T03:00:00+00:00' AIRFLOW_CTX_TRY_NUMBER='1' AIRFLOW_CTX_DAG_RUN_ID='scheduled__2023-01-02T03:00:00+00:00'
[2025-07-24T17:14:08.957+0000] {taskinstance.py:2698} ERROR - Task failed with exception
Traceback (most recent call last):
  File "/home/airflow/.local/lib/python3.8/site-packages/airflow/models/taskinstance.py", line 433, in _execute_task
    result = execute_callable(context=context, **execute_callable_kwargs)
  File "/home/airflow/.local/lib/python3.8/site-packages/airflow/operators/python.py", line 199, in execute
    return_value = self.execute_callable()
  File "/home/airflow/.local/lib/python3.8/site-packages/airflow/operators/python.py", line 216, in execute_callable
    return self.python_callable(*self.op_args, **self.op_kwargs)
  File "/opt/airflow/dags/etl_pipeline.py", line 179, in <lambda>
    python_callable=lambda: load_table(SqlQueries.user_table_insert, 'users'),
  File "/opt/airflow/dags/etl_pipeline.py", line 132, in load_table
    cur.execute(f"INSERT INTO {table} {query}")
psycopg2.errors.UniqueViolation: duplicate key value violates unique constraint "users_pkey"
DETAIL:  Key (userid)=(88) already exists.

[2025-07-24T17:14:09.018+0000] {taskinstance.py:1138} INFO - Marking task as UP_FOR_RETRY. dag_id=tune_stream_dag, task_id=Load_user_dim_table, execution_date=20230102T030000, start_date=20250724T171407, end_date=20250724T171409
[2025-07-24T17:14:09.103+0000] {standard_task_runner.py:107} ERROR - Failed to execute job 2053 for task Load_user_dim_table (duplicate key value violates unique constraint "users_pkey"
DETAIL:  Key (userid)=(88) already exists.
; 1349)
[2025-07-24T17:14:09.176+0000] {local_task_job_runner.py:234} INFO - Task exited with return code 1
[2025-07-24T17:14:10.209+0000] {taskinstance.py:3280} INFO - 0 downstream tasks scheduled from follow-on schedule check
