[2025-07-24T16:04:35.670+0000] {taskinstance.py:1956} INFO - Dependencies all met for dep_context=non-requeueable deps ti=<TaskInstance: tune_stream_dag.Load_user_dim_table scheduled__2023-01-02T05:00:00+00:00 [queued]>
[2025-07-24T16:04:35.677+0000] {taskinstance.py:1956} INFO - Dependencies all met for dep_context=requeueable deps ti=<TaskInstance: tune_stream_dag.Load_user_dim_table scheduled__2023-01-02T05:00:00+00:00 [queued]>
[2025-07-24T16:04:35.678+0000] {taskinstance.py:2170} INFO - Starting attempt 2 of 4
[2025-07-24T16:04:35.693+0000] {taskinstance.py:2191} INFO - Executing <Task(PythonOperator): Load_user_dim_table> on 2023-01-02 05:00:00+00:00
[2025-07-24T16:04:35.700+0000] {standard_task_runner.py:60} INFO - Started process 1621 to run task
[2025-07-24T16:04:35.703+0000] {standard_task_runner.py:87} INFO - Running: ['***', 'tasks', 'run', 'tune_stream_dag', 'Load_user_dim_table', 'scheduled__2023-01-02T05:00:00+00:00', '--job-id', '1298', '--raw', '--subdir', 'DAGS_FOLDER/etl_pipeline.py', '--cfg-path', '/tmp/tmpwi3xadn3']
[2025-07-24T16:04:35.705+0000] {standard_task_runner.py:88} INFO - Job 1298: Subtask Load_user_dim_table
[2025-07-24T16:04:35.775+0000] {task_command.py:423} INFO - Running <TaskInstance: tune_stream_dag.Load_user_dim_table scheduled__2023-01-02T05:00:00+00:00 [running]> on host c53547d84df1
[2025-07-24T16:04:35.848+0000] {taskinstance.py:2480} INFO - Exporting env vars: AIRFLOW_CTX_DAG_OWNER='genz-legend' AIRFLOW_CTX_DAG_ID='tune_stream_dag' AIRFLOW_CTX_TASK_ID='Load_user_dim_table' AIRFLOW_CTX_EXECUTION_DATE='2023-01-02T05:00:00+00:00' AIRFLOW_CTX_TRY_NUMBER='2' AIRFLOW_CTX_DAG_RUN_ID='scheduled__2023-01-02T05:00:00+00:00'
[2025-07-24T16:04:35.857+0000] {taskinstance.py:2698} ERROR - Task failed with exception
Traceback (most recent call last):
  File "/home/airflow/.local/lib/python3.8/site-packages/airflow/models/taskinstance.py", line 433, in _execute_task
    result = execute_callable(context=context, **execute_callable_kwargs)
  File "/home/airflow/.local/lib/python3.8/site-packages/airflow/operators/python.py", line 199, in execute
    return_value = self.execute_callable()
  File "/home/airflow/.local/lib/python3.8/site-packages/airflow/operators/python.py", line 216, in execute_callable
    return self.python_callable(*self.op_args, **self.op_kwargs)
  File "/opt/airflow/dags/etl_pipeline.py", line 179, in <lambda>
    python_callable=lambda: load_table(SqlQueries.user_table_insert, 'users'),
  File "/opt/airflow/dags/etl_pipeline.py", line 132, in load_table
    cur.execute(f"INSERT INTO {table} {query}")
psycopg2.errors.UniqueViolation: duplicate key value violates unique constraint "users_pkey"
DETAIL:  Key (userid)=(88) already exists.

[2025-07-24T16:04:35.870+0000] {taskinstance.py:1138} INFO - Marking task as UP_FOR_RETRY. dag_id=tune_stream_dag, task_id=Load_user_dim_table, execution_date=20230102T050000, start_date=20250724T160435, end_date=20250724T160435
[2025-07-24T16:04:35.880+0000] {standard_task_runner.py:107} ERROR - Failed to execute job 1298 for task Load_user_dim_table (duplicate key value violates unique constraint "users_pkey"
DETAIL:  Key (userid)=(88) already exists.
; 1621)
[2025-07-24T16:04:35.916+0000] {local_task_job_runner.py:234} INFO - Task exited with return code 1
[2025-07-24T16:04:35.939+0000] {taskinstance.py:3280} INFO - 0 downstream tasks scheduled from follow-on schedule check
[2025-07-24T16:42:26.530+0000] {taskinstance.py:1956} INFO - Dependencies all met for dep_context=non-requeueable deps ti=<TaskInstance: tune_stream_dag.Load_user_dim_table scheduled__2023-01-02T05:00:00+00:00 [queued]>
[2025-07-24T16:42:26.550+0000] {taskinstance.py:1956} INFO - Dependencies all met for dep_context=requeueable deps ti=<TaskInstance: tune_stream_dag.Load_user_dim_table scheduled__2023-01-02T05:00:00+00:00 [queued]>
[2025-07-24T16:42:26.552+0000] {taskinstance.py:2170} INFO - Starting attempt 2 of 4
[2025-07-24T16:42:26.572+0000] {taskinstance.py:2191} INFO - Executing <Task(PythonOperator): Load_user_dim_table> on 2023-01-02 05:00:00+00:00
[2025-07-24T16:42:26.587+0000] {standard_task_runner.py:60} INFO - Started process 194 to run task
[2025-07-24T16:42:26.593+0000] {standard_task_runner.py:87} INFO - Running: ['***', 'tasks', 'run', 'tune_stream_dag', 'Load_user_dim_table', 'scheduled__2023-01-02T05:00:00+00:00', '--job-id', '1711', '--raw', '--subdir', 'DAGS_FOLDER/etl_pipeline.py', '--cfg-path', '/tmp/tmpda7i6b0j']
[2025-07-24T16:42:26.598+0000] {standard_task_runner.py:88} INFO - Job 1711: Subtask Load_user_dim_table
[2025-07-24T16:42:26.694+0000] {task_command.py:423} INFO - Running <TaskInstance: tune_stream_dag.Load_user_dim_table scheduled__2023-01-02T05:00:00+00:00 [running]> on host 5def55d2a1b5
[2025-07-24T16:42:26.794+0000] {taskinstance.py:2480} INFO - Exporting env vars: AIRFLOW_CTX_DAG_OWNER='genz-legend' AIRFLOW_CTX_DAG_ID='tune_stream_dag' AIRFLOW_CTX_TASK_ID='Load_user_dim_table' AIRFLOW_CTX_EXECUTION_DATE='2023-01-02T05:00:00+00:00' AIRFLOW_CTX_TRY_NUMBER='2' AIRFLOW_CTX_DAG_RUN_ID='scheduled__2023-01-02T05:00:00+00:00'
[2025-07-24T16:42:26.825+0000] {taskinstance.py:2698} ERROR - Task failed with exception
Traceback (most recent call last):
  File "/home/airflow/.local/lib/python3.8/site-packages/airflow/models/taskinstance.py", line 433, in _execute_task
    result = execute_callable(context=context, **execute_callable_kwargs)
  File "/home/airflow/.local/lib/python3.8/site-packages/airflow/operators/python.py", line 199, in execute
    return_value = self.execute_callable()
  File "/home/airflow/.local/lib/python3.8/site-packages/airflow/operators/python.py", line 216, in execute_callable
    return self.python_callable(*self.op_args, **self.op_kwargs)
  File "/opt/airflow/dags/etl_pipeline.py", line 179, in <lambda>
    python_callable=lambda: load_table(SqlQueries.user_table_insert, 'users'),
  File "/opt/airflow/dags/etl_pipeline.py", line 132, in load_table
    cur.execute(f"INSERT INTO {table} {query}")
psycopg2.errors.UniqueViolation: duplicate key value violates unique constraint "users_pkey"
DETAIL:  Key (userid)=(88) already exists.

[2025-07-24T16:42:26.843+0000] {taskinstance.py:1138} INFO - Marking task as UP_FOR_RETRY. dag_id=tune_stream_dag, task_id=Load_user_dim_table, execution_date=20230102T050000, start_date=20250724T164226, end_date=20250724T164226
[2025-07-24T16:42:26.863+0000] {standard_task_runner.py:107} ERROR - Failed to execute job 1711 for task Load_user_dim_table (duplicate key value violates unique constraint "users_pkey"
DETAIL:  Key (userid)=(88) already exists.
; 194)
[2025-07-24T16:42:26.887+0000] {local_task_job_runner.py:234} INFO - Task exited with return code 1
[2025-07-24T16:42:26.918+0000] {taskinstance.py:3280} INFO - 0 downstream tasks scheduled from follow-on schedule check
[2025-07-24T17:21:10.769+0000] {taskinstance.py:1956} INFO - Dependencies all met for dep_context=non-requeueable deps ti=<TaskInstance: tune_stream_dag.Load_user_dim_table scheduled__2023-01-02T05:00:00+00:00 [queued]>
[2025-07-24T17:21:10.832+0000] {taskinstance.py:1956} INFO - Dependencies all met for dep_context=requeueable deps ti=<TaskInstance: tune_stream_dag.Load_user_dim_table scheduled__2023-01-02T05:00:00+00:00 [queued]>
[2025-07-24T17:21:10.833+0000] {taskinstance.py:2170} INFO - Starting attempt 2 of 4
[2025-07-24T17:21:10.943+0000] {taskinstance.py:2191} INFO - Executing <Task(PythonOperator): Load_user_dim_table> on 2023-01-02 05:00:00+00:00
[2025-07-24T17:21:11.004+0000] {standard_task_runner.py:60} INFO - Started process 1870 to run task
[2025-07-24T17:21:11.086+0000] {standard_task_runner.py:87} INFO - Running: ['***', 'tasks', 'run', 'tune_stream_dag', 'Load_user_dim_table', 'scheduled__2023-01-02T05:00:00+00:00', '--job-id', '2191', '--raw', '--subdir', 'DAGS_FOLDER/etl_pipeline.py', '--cfg-path', '/tmp/tmps7mdsznb']
[2025-07-24T17:21:11.092+0000] {standard_task_runner.py:88} INFO - Job 2191: Subtask Load_user_dim_table
[2025-07-24T17:21:11.527+0000] {task_command.py:423} INFO - Running <TaskInstance: tune_stream_dag.Load_user_dim_table scheduled__2023-01-02T05:00:00+00:00 [running]> on host 5def55d2a1b5
[2025-07-24T17:21:11.958+0000] {taskinstance.py:2480} INFO - Exporting env vars: AIRFLOW_CTX_DAG_OWNER='genz-legend' AIRFLOW_CTX_DAG_ID='tune_stream_dag' AIRFLOW_CTX_TASK_ID='Load_user_dim_table' AIRFLOW_CTX_EXECUTION_DATE='2023-01-02T05:00:00+00:00' AIRFLOW_CTX_TRY_NUMBER='2' AIRFLOW_CTX_DAG_RUN_ID='scheduled__2023-01-02T05:00:00+00:00'
[2025-07-24T17:21:12.700+0000] {python.py:201} INFO - Done. Returned value was: None
[2025-07-24T17:21:12.764+0000] {taskinstance.py:1138} INFO - Marking task as SUCCESS. dag_id=tune_stream_dag, task_id=Load_user_dim_table, execution_date=20230102T050000, start_date=20250724T172110, end_date=20250724T172112
[2025-07-24T17:21:13.134+0000] {local_task_job_runner.py:234} INFO - Task exited with return code 0
[2025-07-24T17:21:13.506+0000] {taskinstance.py:3280} INFO - 0 downstream tasks scheduled from follow-on schedule check
