[2025-07-24T15:54:15.443+0000] {taskinstance.py:1956} INFO - Dependencies all met for dep_context=non-requeueable deps ti=<TaskInstance: tune_stream_dag.Load_user_dim_table scheduled__2023-01-01T03:00:00+00:00 [queued]>
[2025-07-24T15:54:15.452+0000] {taskinstance.py:1956} INFO - Dependencies all met for dep_context=requeueable deps ti=<TaskInstance: tune_stream_dag.Load_user_dim_table scheduled__2023-01-01T03:00:00+00:00 [queued]>
[2025-07-24T15:54:15.452+0000] {taskinstance.py:2170} INFO - Starting attempt 4 of 4
[2025-07-24T15:54:15.464+0000] {taskinstance.py:2191} INFO - Executing <Task(PythonOperator): Load_user_dim_table> on 2023-01-01 03:00:00+00:00
[2025-07-24T15:54:15.469+0000] {standard_task_runner.py:60} INFO - Started process 1149 to run task
[2025-07-24T15:54:15.474+0000] {standard_task_runner.py:87} INFO - Running: ['***', 'tasks', 'run', 'tune_stream_dag', 'Load_user_dim_table', 'scheduled__2023-01-01T03:00:00+00:00', '--job-id', '1192', '--raw', '--subdir', 'DAGS_FOLDER/etl_pipeline.py', '--cfg-path', '/tmp/tmp9rxnei3u']
[2025-07-24T15:54:15.476+0000] {standard_task_runner.py:88} INFO - Job 1192: Subtask Load_user_dim_table
[2025-07-24T15:54:15.533+0000] {task_command.py:423} INFO - Running <TaskInstance: tune_stream_dag.Load_user_dim_table scheduled__2023-01-01T03:00:00+00:00 [running]> on host c53547d84df1
[2025-07-24T15:54:15.599+0000] {taskinstance.py:2480} INFO - Exporting env vars: AIRFLOW_CTX_DAG_OWNER='genz-legend' AIRFLOW_CTX_DAG_ID='tune_stream_dag' AIRFLOW_CTX_TASK_ID='Load_user_dim_table' AIRFLOW_CTX_EXECUTION_DATE='2023-01-01T03:00:00+00:00' AIRFLOW_CTX_TRY_NUMBER='4' AIRFLOW_CTX_DAG_RUN_ID='scheduled__2023-01-01T03:00:00+00:00'
[2025-07-24T15:54:15.607+0000] {taskinstance.py:2698} ERROR - Task failed with exception
Traceback (most recent call last):
  File "/home/airflow/.local/lib/python3.8/site-packages/airflow/models/taskinstance.py", line 433, in _execute_task
    result = execute_callable(context=context, **execute_callable_kwargs)
  File "/home/airflow/.local/lib/python3.8/site-packages/airflow/operators/python.py", line 199, in execute
    return_value = self.execute_callable()
  File "/home/airflow/.local/lib/python3.8/site-packages/airflow/operators/python.py", line 216, in execute_callable
    return self.python_callable(*self.op_args, **self.op_kwargs)
  File "/opt/airflow/dags/etl_pipeline.py", line 179, in <lambda>
    python_callable=lambda: load_table(SqlQueries.user_table_insert, 'users'),
  File "/opt/airflow/dags/etl_pipeline.py", line 132, in load_table
    cur.execute(f"INSERT INTO {table} {query}")
psycopg2.errors.UniqueViolation: duplicate key value violates unique constraint "users_pkey"
DETAIL:  Key (userid)=(88) already exists.

[2025-07-24T15:54:15.620+0000] {taskinstance.py:1138} INFO - Marking task as FAILED. dag_id=tune_stream_dag, task_id=Load_user_dim_table, execution_date=20230101T030000, start_date=20250724T155415, end_date=20250724T155415
[2025-07-24T15:54:15.630+0000] {standard_task_runner.py:107} ERROR - Failed to execute job 1192 for task Load_user_dim_table (duplicate key value violates unique constraint "users_pkey"
DETAIL:  Key (userid)=(88) already exists.
; 1149)
[2025-07-24T15:54:15.646+0000] {local_task_job_runner.py:234} INFO - Task exited with return code 1
[2025-07-24T15:54:15.663+0000] {taskinstance.py:3280} INFO - 0 downstream tasks scheduled from follow-on schedule check
[2025-07-24T16:32:52.958+0000] {taskinstance.py:1956} INFO - Dependencies all met for dep_context=non-requeueable deps ti=<TaskInstance: tune_stream_dag.Load_user_dim_table scheduled__2023-01-01T03:00:00+00:00 [queued]>
[2025-07-24T16:32:52.968+0000] {taskinstance.py:1956} INFO - Dependencies all met for dep_context=requeueable deps ti=<TaskInstance: tune_stream_dag.Load_user_dim_table scheduled__2023-01-01T03:00:00+00:00 [queued]>
[2025-07-24T16:32:52.969+0000] {taskinstance.py:2170} INFO - Starting attempt 4 of 4
[2025-07-24T16:32:52.980+0000] {taskinstance.py:2191} INFO - Executing <Task(PythonOperator): Load_user_dim_table> on 2023-01-01 03:00:00+00:00
[2025-07-24T16:32:52.988+0000] {standard_task_runner.py:60} INFO - Started process 956 to run task
[2025-07-24T16:32:52.991+0000] {standard_task_runner.py:87} INFO - Running: ['***', 'tasks', 'run', 'tune_stream_dag', 'Load_user_dim_table', 'scheduled__2023-01-01T03:00:00+00:00', '--job-id', '1536', '--raw', '--subdir', 'DAGS_FOLDER/etl_pipeline.py', '--cfg-path', '/tmp/tmpzzdoo_ul']
[2025-07-24T16:32:52.993+0000] {standard_task_runner.py:88} INFO - Job 1536: Subtask Load_user_dim_table
[2025-07-24T16:32:53.061+0000] {task_command.py:423} INFO - Running <TaskInstance: tune_stream_dag.Load_user_dim_table scheduled__2023-01-01T03:00:00+00:00 [running]> on host c53547d84df1
[2025-07-24T16:32:53.135+0000] {taskinstance.py:2480} INFO - Exporting env vars: AIRFLOW_CTX_DAG_OWNER='genz-legend' AIRFLOW_CTX_DAG_ID='tune_stream_dag' AIRFLOW_CTX_TASK_ID='Load_user_dim_table' AIRFLOW_CTX_EXECUTION_DATE='2023-01-01T03:00:00+00:00' AIRFLOW_CTX_TRY_NUMBER='4' AIRFLOW_CTX_DAG_RUN_ID='scheduled__2023-01-01T03:00:00+00:00'
[2025-07-24T16:32:53.210+0000] {taskinstance.py:2698} ERROR - Task failed with exception
Traceback (most recent call last):
  File "/home/airflow/.local/lib/python3.8/site-packages/airflow/models/taskinstance.py", line 433, in _execute_task
    result = execute_callable(context=context, **execute_callable_kwargs)
  File "/home/airflow/.local/lib/python3.8/site-packages/airflow/operators/python.py", line 199, in execute
    return_value = self.execute_callable()
  File "/home/airflow/.local/lib/python3.8/site-packages/airflow/operators/python.py", line 216, in execute_callable
    return self.python_callable(*self.op_args, **self.op_kwargs)
  File "/opt/airflow/dags/etl_pipeline.py", line 179, in <lambda>
    python_callable=lambda: load_table(SqlQueries.user_table_insert, 'users'),
  File "/opt/airflow/dags/etl_pipeline.py", line 132, in load_table
    cur.execute(f"INSERT INTO {table} {query}")
psycopg2.errors.UniqueViolation: duplicate key value violates unique constraint "users_pkey"
DETAIL:  Key (userid)=(88) already exists.

[2025-07-24T16:32:53.223+0000] {taskinstance.py:1138} INFO - Marking task as FAILED. dag_id=tune_stream_dag, task_id=Load_user_dim_table, execution_date=20230101T030000, start_date=20250724T163252, end_date=20250724T163253
[2025-07-24T16:32:53.235+0000] {standard_task_runner.py:107} ERROR - Failed to execute job 1536 for task Load_user_dim_table (duplicate key value violates unique constraint "users_pkey"
DETAIL:  Key (userid)=(88) already exists.
; 956)
[2025-07-24T16:32:53.245+0000] {local_task_job_runner.py:234} INFO - Task exited with return code 1
[2025-07-24T16:32:53.268+0000] {taskinstance.py:3280} INFO - 0 downstream tasks scheduled from follow-on schedule check
[2025-07-24T17:11:59.265+0000] {taskinstance.py:1956} INFO - Dependencies all met for dep_context=non-requeueable deps ti=<TaskInstance: tune_stream_dag.Load_user_dim_table scheduled__2023-01-01T03:00:00+00:00 [queued]>
[2025-07-24T17:11:59.274+0000] {taskinstance.py:1956} INFO - Dependencies all met for dep_context=requeueable deps ti=<TaskInstance: tune_stream_dag.Load_user_dim_table scheduled__2023-01-01T03:00:00+00:00 [queued]>
[2025-07-24T17:11:59.275+0000] {taskinstance.py:2170} INFO - Starting attempt 4 of 4
[2025-07-24T17:11:59.286+0000] {taskinstance.py:2191} INFO - Executing <Task(PythonOperator): Load_user_dim_table> on 2023-01-01 03:00:00+00:00
[2025-07-24T17:11:59.292+0000] {standard_task_runner.py:60} INFO - Started process 933 to run task
[2025-07-24T17:11:59.294+0000] {standard_task_runner.py:87} INFO - Running: ['***', 'tasks', 'run', 'tune_stream_dag', 'Load_user_dim_table', 'scheduled__2023-01-01T03:00:00+00:00', '--job-id', '1928', '--raw', '--subdir', 'DAGS_FOLDER/etl_pipeline.py', '--cfg-path', '/tmp/tmpzpe6n8__']
[2025-07-24T17:11:59.297+0000] {standard_task_runner.py:88} INFO - Job 1928: Subtask Load_user_dim_table
[2025-07-24T17:11:59.365+0000] {task_command.py:423} INFO - Running <TaskInstance: tune_stream_dag.Load_user_dim_table scheduled__2023-01-01T03:00:00+00:00 [running]> on host 5def55d2a1b5
[2025-07-24T17:11:59.429+0000] {taskinstance.py:2480} INFO - Exporting env vars: AIRFLOW_CTX_DAG_OWNER='genz-legend' AIRFLOW_CTX_DAG_ID='tune_stream_dag' AIRFLOW_CTX_TASK_ID='Load_user_dim_table' AIRFLOW_CTX_EXECUTION_DATE='2023-01-01T03:00:00+00:00' AIRFLOW_CTX_TRY_NUMBER='4' AIRFLOW_CTX_DAG_RUN_ID='scheduled__2023-01-01T03:00:00+00:00'
[2025-07-24T17:11:59.445+0000] {taskinstance.py:2698} ERROR - Task failed with exception
Traceback (most recent call last):
  File "/home/airflow/.local/lib/python3.8/site-packages/airflow/models/taskinstance.py", line 433, in _execute_task
    result = execute_callable(context=context, **execute_callable_kwargs)
  File "/home/airflow/.local/lib/python3.8/site-packages/airflow/operators/python.py", line 199, in execute
    return_value = self.execute_callable()
  File "/home/airflow/.local/lib/python3.8/site-packages/airflow/operators/python.py", line 216, in execute_callable
    return self.python_callable(*self.op_args, **self.op_kwargs)
  File "/opt/airflow/dags/etl_pipeline.py", line 179, in <lambda>
    python_callable=lambda: load_table(SqlQueries.user_table_insert, 'users'),
  File "/opt/airflow/dags/etl_pipeline.py", line 132, in load_table
    cur.execute(f"INSERT INTO {table} {query}")
psycopg2.errors.UniqueViolation: duplicate key value violates unique constraint "users_pkey"
DETAIL:  Key (userid)=(88) already exists.

[2025-07-24T17:11:59.458+0000] {taskinstance.py:1138} INFO - Marking task as FAILED. dag_id=tune_stream_dag, task_id=Load_user_dim_table, execution_date=20230101T030000, start_date=20250724T171159, end_date=20250724T171159
[2025-07-24T17:11:59.471+0000] {standard_task_runner.py:107} ERROR - Failed to execute job 1928 for task Load_user_dim_table (duplicate key value violates unique constraint "users_pkey"
DETAIL:  Key (userid)=(88) already exists.
; 933)
[2025-07-24T17:11:59.508+0000] {local_task_job_runner.py:234} INFO - Task exited with return code 1
[2025-07-24T17:11:59.536+0000] {taskinstance.py:3280} INFO - 0 downstream tasks scheduled from follow-on schedule check
