[2025-07-24T15:59:23.453+0000] {taskinstance.py:1956} INFO - Dependencies all met for dep_context=non-requeueable deps ti=<TaskInstance: tune_stream_dag.Load_user_dim_table scheduled__2023-01-01T15:00:00+00:00 [queued]>
[2025-07-24T15:59:23.464+0000] {taskinstance.py:1956} INFO - Dependencies all met for dep_context=requeueable deps ti=<TaskInstance: tune_stream_dag.Load_user_dim_table scheduled__2023-01-01T15:00:00+00:00 [queued]>
[2025-07-24T15:59:23.464+0000] {taskinstance.py:2170} INFO - Starting attempt 3 of 4
[2025-07-24T15:59:23.479+0000] {taskinstance.py:2191} INFO - Executing <Task(PythonOperator): Load_user_dim_table> on 2023-01-01 15:00:00+00:00
[2025-07-24T15:59:23.487+0000] {standard_task_runner.py:60} INFO - Started process 1387 to run task
[2025-07-24T15:59:23.491+0000] {standard_task_runner.py:87} INFO - Running: ['***', 'tasks', 'run', 'tune_stream_dag', 'Load_user_dim_table', 'scheduled__2023-01-01T15:00:00+00:00', '--job-id', '1244', '--raw', '--subdir', 'DAGS_FOLDER/etl_pipeline.py', '--cfg-path', '/tmp/tmp89yt8ddk']
[2025-07-24T15:59:23.494+0000] {standard_task_runner.py:88} INFO - Job 1244: Subtask Load_user_dim_table
[2025-07-24T15:59:23.560+0000] {task_command.py:423} INFO - Running <TaskInstance: tune_stream_dag.Load_user_dim_table scheduled__2023-01-01T15:00:00+00:00 [running]> on host c53547d84df1
[2025-07-24T15:59:23.627+0000] {taskinstance.py:2480} INFO - Exporting env vars: AIRFLOW_CTX_DAG_OWNER='genz-legend' AIRFLOW_CTX_DAG_ID='tune_stream_dag' AIRFLOW_CTX_TASK_ID='Load_user_dim_table' AIRFLOW_CTX_EXECUTION_DATE='2023-01-01T15:00:00+00:00' AIRFLOW_CTX_TRY_NUMBER='3' AIRFLOW_CTX_DAG_RUN_ID='scheduled__2023-01-01T15:00:00+00:00'
[2025-07-24T15:59:25.293+0000] {taskinstance.py:2698} ERROR - Task failed with exception
Traceback (most recent call last):
  File "/home/airflow/.local/lib/python3.8/site-packages/airflow/models/taskinstance.py", line 433, in _execute_task
    result = execute_callable(context=context, **execute_callable_kwargs)
  File "/home/airflow/.local/lib/python3.8/site-packages/airflow/operators/python.py", line 199, in execute
    return_value = self.execute_callable()
  File "/home/airflow/.local/lib/python3.8/site-packages/airflow/operators/python.py", line 216, in execute_callable
    return self.python_callable(*self.op_args, **self.op_kwargs)
  File "/opt/airflow/dags/etl_pipeline.py", line 179, in <lambda>
    python_callable=lambda: load_table(SqlQueries.user_table_insert, 'users'),
  File "/opt/airflow/dags/etl_pipeline.py", line 132, in load_table
    cur.execute(f"INSERT INTO {table} {query}")
psycopg2.errors.UniqueViolation: duplicate key value violates unique constraint "users_pkey"
DETAIL:  Key (userid)=(88) already exists.

[2025-07-24T15:59:25.308+0000] {taskinstance.py:1138} INFO - Marking task as UP_FOR_RETRY. dag_id=tune_stream_dag, task_id=Load_user_dim_table, execution_date=20230101T150000, start_date=20250724T155923, end_date=20250724T155925
[2025-07-24T15:59:25.428+0000] {standard_task_runner.py:107} ERROR - Failed to execute job 1244 for task Load_user_dim_table (duplicate key value violates unique constraint "users_pkey"
DETAIL:  Key (userid)=(88) already exists.
; 1387)
[2025-07-24T15:59:25.471+0000] {local_task_job_runner.py:234} INFO - Task exited with return code 1
[2025-07-24T15:59:25.498+0000] {taskinstance.py:3280} INFO - 0 downstream tasks scheduled from follow-on schedule check
[2025-07-24T16:47:17.222+0000] {taskinstance.py:1956} INFO - Dependencies all met for dep_context=non-requeueable deps ti=<TaskInstance: tune_stream_dag.Load_user_dim_table scheduled__2023-01-01T15:00:00+00:00 [queued]>
[2025-07-24T16:47:17.256+0000] {taskinstance.py:1956} INFO - Dependencies all met for dep_context=requeueable deps ti=<TaskInstance: tune_stream_dag.Load_user_dim_table scheduled__2023-01-01T15:00:00+00:00 [queued]>
[2025-07-24T16:47:17.257+0000] {taskinstance.py:2170} INFO - Starting attempt 3 of 4
[2025-07-24T16:47:17.291+0000] {taskinstance.py:2191} INFO - Executing <Task(PythonOperator): Load_user_dim_table> on 2023-01-01 15:00:00+00:00
[2025-07-24T16:47:17.320+0000] {standard_task_runner.py:60} INFO - Started process 310 to run task
[2025-07-24T16:47:17.335+0000] {standard_task_runner.py:87} INFO - Running: ['***', 'tasks', 'run', 'tune_stream_dag', 'Load_user_dim_table', 'scheduled__2023-01-01T15:00:00+00:00', '--job-id', '1723', '--raw', '--subdir', 'DAGS_FOLDER/etl_pipeline.py', '--cfg-path', '/tmp/tmpwwv0zg4y']
[2025-07-24T16:47:17.341+0000] {standard_task_runner.py:88} INFO - Job 1723: Subtask Load_user_dim_table
[2025-07-24T16:47:17.547+0000] {task_command.py:423} INFO - Running <TaskInstance: tune_stream_dag.Load_user_dim_table scheduled__2023-01-01T15:00:00+00:00 [running]> on host 5def55d2a1b5
[2025-07-24T16:47:17.820+0000] {taskinstance.py:2480} INFO - Exporting env vars: AIRFLOW_CTX_DAG_OWNER='genz-legend' AIRFLOW_CTX_DAG_ID='tune_stream_dag' AIRFLOW_CTX_TASK_ID='Load_user_dim_table' AIRFLOW_CTX_EXECUTION_DATE='2023-01-01T15:00:00+00:00' AIRFLOW_CTX_TRY_NUMBER='3' AIRFLOW_CTX_DAG_RUN_ID='scheduled__2023-01-01T15:00:00+00:00'
[2025-07-24T16:47:17.843+0000] {taskinstance.py:2698} ERROR - Task failed with exception
Traceback (most recent call last):
  File "/home/airflow/.local/lib/python3.8/site-packages/airflow/models/taskinstance.py", line 433, in _execute_task
    result = execute_callable(context=context, **execute_callable_kwargs)
  File "/home/airflow/.local/lib/python3.8/site-packages/airflow/operators/python.py", line 199, in execute
    return_value = self.execute_callable()
  File "/home/airflow/.local/lib/python3.8/site-packages/airflow/operators/python.py", line 216, in execute_callable
    return self.python_callable(*self.op_args, **self.op_kwargs)
  File "/opt/airflow/dags/etl_pipeline.py", line 179, in <lambda>
    python_callable=lambda: load_table(SqlQueries.user_table_insert, 'users'),
  File "/opt/airflow/dags/etl_pipeline.py", line 131, in load_table
    cur.execute(f"TRUNCATE TABLE {table}")
psycopg2.errors.UndefinedTable: relation "users" does not exist

[2025-07-24T16:47:17.877+0000] {taskinstance.py:1138} INFO - Marking task as UP_FOR_RETRY. dag_id=tune_stream_dag, task_id=Load_user_dim_table, execution_date=20230101T150000, start_date=20250724T164717, end_date=20250724T164717
[2025-07-24T16:47:17.898+0000] {standard_task_runner.py:107} ERROR - Failed to execute job 1723 for task Load_user_dim_table (relation "users" does not exist
; 310)
[2025-07-24T16:47:17.955+0000] {local_task_job_runner.py:234} INFO - Task exited with return code 1
[2025-07-24T16:47:18.013+0000] {taskinstance.py:3280} INFO - 0 downstream tasks scheduled from follow-on schedule check
