[2025-07-24T16:04:27.254+0000] {taskinstance.py:1956} INFO - Dependencies all met for dep_context=non-requeueable deps ti=<TaskInstance: tune_stream_dag.Load_user_dim_table scheduled__2023-01-01T15:00:00+00:00 [queued]>
[2025-07-24T16:04:27.263+0000] {taskinstance.py:1956} INFO - Dependencies all met for dep_context=requeueable deps ti=<TaskInstance: tune_stream_dag.Load_user_dim_table scheduled__2023-01-01T15:00:00+00:00 [queued]>
[2025-07-24T16:04:27.265+0000] {taskinstance.py:2170} INFO - Starting attempt 4 of 4
[2025-07-24T16:04:27.278+0000] {taskinstance.py:2191} INFO - Executing <Task(PythonOperator): Load_user_dim_table> on 2023-01-01 15:00:00+00:00
[2025-07-24T16:04:27.284+0000] {standard_task_runner.py:60} INFO - Started process 1586 to run task
[2025-07-24T16:04:27.286+0000] {standard_task_runner.py:87} INFO - Running: ['***', 'tasks', 'run', 'tune_stream_dag', 'Load_user_dim_table', 'scheduled__2023-01-01T15:00:00+00:00', '--job-id', '1287', '--raw', '--subdir', 'DAGS_FOLDER/etl_pipeline.py', '--cfg-path', '/tmp/tmpt5gcovlm']
[2025-07-24T16:04:27.289+0000] {standard_task_runner.py:88} INFO - Job 1287: Subtask Load_user_dim_table
[2025-07-24T16:04:27.349+0000] {task_command.py:423} INFO - Running <TaskInstance: tune_stream_dag.Load_user_dim_table scheduled__2023-01-01T15:00:00+00:00 [running]> on host c53547d84df1
[2025-07-24T16:04:27.413+0000] {taskinstance.py:2480} INFO - Exporting env vars: AIRFLOW_CTX_DAG_OWNER='genz-legend' AIRFLOW_CTX_DAG_ID='tune_stream_dag' AIRFLOW_CTX_TASK_ID='Load_user_dim_table' AIRFLOW_CTX_EXECUTION_DATE='2023-01-01T15:00:00+00:00' AIRFLOW_CTX_TRY_NUMBER='4' AIRFLOW_CTX_DAG_RUN_ID='scheduled__2023-01-01T15:00:00+00:00'
[2025-07-24T16:04:27.424+0000] {taskinstance.py:2698} ERROR - Task failed with exception
Traceback (most recent call last):
  File "/home/airflow/.local/lib/python3.8/site-packages/airflow/models/taskinstance.py", line 433, in _execute_task
    result = execute_callable(context=context, **execute_callable_kwargs)
  File "/home/airflow/.local/lib/python3.8/site-packages/airflow/operators/python.py", line 199, in execute
    return_value = self.execute_callable()
  File "/home/airflow/.local/lib/python3.8/site-packages/airflow/operators/python.py", line 216, in execute_callable
    return self.python_callable(*self.op_args, **self.op_kwargs)
  File "/opt/airflow/dags/etl_pipeline.py", line 179, in <lambda>
    python_callable=lambda: load_table(SqlQueries.user_table_insert, 'users'),
  File "/opt/airflow/dags/etl_pipeline.py", line 132, in load_table
    cur.execute(f"INSERT INTO {table} {query}")
psycopg2.errors.UniqueViolation: duplicate key value violates unique constraint "users_pkey"
DETAIL:  Key (userid)=(88) already exists.

[2025-07-24T16:04:27.434+0000] {taskinstance.py:1138} INFO - Marking task as FAILED. dag_id=tune_stream_dag, task_id=Load_user_dim_table, execution_date=20230101T150000, start_date=20250724T160427, end_date=20250724T160427
[2025-07-24T16:04:27.444+0000] {standard_task_runner.py:107} ERROR - Failed to execute job 1287 for task Load_user_dim_table (duplicate key value violates unique constraint "users_pkey"
DETAIL:  Key (userid)=(88) already exists.
; 1586)
[2025-07-24T16:04:27.461+0000] {local_task_job_runner.py:234} INFO - Task exited with return code 1
[2025-07-24T16:04:27.485+0000] {taskinstance.py:3280} INFO - 0 downstream tasks scheduled from follow-on schedule check
