[2025-07-24T16:04:57.713+0000] {taskinstance.py:1956} INFO - Dependencies all met for dep_context=non-requeueable deps ti=<TaskInstance: tune_stream_dag.Load_time_dim_table scheduled__2023-01-01T19:00:00+00:00 [queued]>
[2025-07-24T16:04:57.770+0000] {taskinstance.py:1956} INFO - Dependencies all met for dep_context=requeueable deps ti=<TaskInstance: tune_stream_dag.Load_time_dim_table scheduled__2023-01-01T19:00:00+00:00 [queued]>
[2025-07-24T16:04:57.786+0000] {taskinstance.py:2170} INFO - Starting attempt 1 of 4
[2025-07-24T16:04:57.845+0000] {taskinstance.py:2191} INFO - Executing <Task(PythonOperator): Load_time_dim_table> on 2023-01-01 19:00:00+00:00
[2025-07-24T16:04:57.869+0000] {standard_task_runner.py:60} INFO - Started process 1705 to run task
[2025-07-24T16:04:57.879+0000] {standard_task_runner.py:87} INFO - Running: ['***', 'tasks', 'run', 'tune_stream_dag', 'Load_time_dim_table', 'scheduled__2023-01-01T19:00:00+00:00', '--job-id', '1321', '--raw', '--subdir', 'DAGS_FOLDER/etl_pipeline.py', '--cfg-path', '/tmp/tmp8r8yl9dt']
[2025-07-24T16:04:57.895+0000] {standard_task_runner.py:88} INFO - Job 1321: Subtask Load_time_dim_table
[2025-07-24T16:04:58.301+0000] {task_command.py:423} INFO - Running <TaskInstance: tune_stream_dag.Load_time_dim_table scheduled__2023-01-01T19:00:00+00:00 [running]> on host c53547d84df1
[2025-07-24T16:04:58.771+0000] {taskinstance.py:2480} INFO - Exporting env vars: AIRFLOW_CTX_DAG_OWNER='genz-legend' AIRFLOW_CTX_DAG_ID='tune_stream_dag' AIRFLOW_CTX_TASK_ID='Load_time_dim_table' AIRFLOW_CTX_EXECUTION_DATE='2023-01-01T19:00:00+00:00' AIRFLOW_CTX_TRY_NUMBER='1' AIRFLOW_CTX_DAG_RUN_ID='scheduled__2023-01-01T19:00:00+00:00'
[2025-07-24T16:04:58.841+0000] {taskinstance.py:2698} ERROR - Task failed with exception
Traceback (most recent call last):
  File "/home/airflow/.local/lib/python3.8/site-packages/airflow/models/taskinstance.py", line 433, in _execute_task
    result = execute_callable(context=context, **execute_callable_kwargs)
  File "/home/airflow/.local/lib/python3.8/site-packages/airflow/operators/python.py", line 199, in execute
    return_value = self.execute_callable()
  File "/home/airflow/.local/lib/python3.8/site-packages/airflow/operators/python.py", line 216, in execute_callable
    return self.python_callable(*self.op_args, **self.op_kwargs)
  File "/opt/airflow/dags/etl_pipeline.py", line 197, in <lambda>
    python_callable=lambda: load_table(SqlQueries.time_table_insert, 'time'),
  File "/opt/airflow/dags/etl_pipeline.py", line 132, in load_table
    cur.execute(f"INSERT INTO {table} {query}")
psycopg2.errors.InvalidParameterValue: timestamp units "dayofweek" not recognized

[2025-07-24T16:04:58.951+0000] {taskinstance.py:1138} INFO - Marking task as UP_FOR_RETRY. dag_id=tune_stream_dag, task_id=Load_time_dim_table, execution_date=20230101T190000, start_date=20250724T160457, end_date=20250724T160458
[2025-07-24T16:04:59.084+0000] {standard_task_runner.py:107} ERROR - Failed to execute job 1321 for task Load_time_dim_table (timestamp units "dayofweek" not recognized
; 1705)
[2025-07-24T16:04:59.202+0000] {local_task_job_runner.py:234} INFO - Task exited with return code 1
[2025-07-24T16:04:59.350+0000] {taskinstance.py:3280} INFO - 0 downstream tasks scheduled from follow-on schedule check
[2025-07-24T16:34:54.238+0000] {taskinstance.py:1956} INFO - Dependencies all met for dep_context=non-requeueable deps ti=<TaskInstance: tune_stream_dag.Load_time_dim_table scheduled__2023-01-01T19:00:00+00:00 [queued]>
[2025-07-24T16:34:54.356+0000] {taskinstance.py:1956} INFO - Dependencies all met for dep_context=requeueable deps ti=<TaskInstance: tune_stream_dag.Load_time_dim_table scheduled__2023-01-01T19:00:00+00:00 [queued]>
[2025-07-24T16:34:54.356+0000] {taskinstance.py:2170} INFO - Starting attempt 1 of 4
[2025-07-24T16:34:54.533+0000] {taskinstance.py:2191} INFO - Executing <Task(PythonOperator): Load_time_dim_table> on 2023-01-01 19:00:00+00:00
[2025-07-24T16:34:54.605+0000] {standard_task_runner.py:60} INFO - Started process 1311 to run task
[2025-07-24T16:34:54.614+0000] {standard_task_runner.py:87} INFO - Running: ['***', 'tasks', 'run', 'tune_stream_dag', 'Load_time_dim_table', 'scheduled__2023-01-01T19:00:00+00:00', '--job-id', '1640', '--raw', '--subdir', 'DAGS_FOLDER/etl_pipeline.py', '--cfg-path', '/tmp/tmp6x6oa3h0']
[2025-07-24T16:34:54.730+0000] {standard_task_runner.py:88} INFO - Job 1640: Subtask Load_time_dim_table
[2025-07-24T16:34:55.170+0000] {task_command.py:423} INFO - Running <TaskInstance: tune_stream_dag.Load_time_dim_table scheduled__2023-01-01T19:00:00+00:00 [running]> on host c53547d84df1
[2025-07-24T16:34:55.414+0000] {taskinstance.py:2480} INFO - Exporting env vars: AIRFLOW_CTX_DAG_OWNER='genz-legend' AIRFLOW_CTX_DAG_ID='tune_stream_dag' AIRFLOW_CTX_TASK_ID='Load_time_dim_table' AIRFLOW_CTX_EXECUTION_DATE='2023-01-01T19:00:00+00:00' AIRFLOW_CTX_TRY_NUMBER='1' AIRFLOW_CTX_DAG_RUN_ID='scheduled__2023-01-01T19:00:00+00:00'
[2025-07-24T16:34:55.619+0000] {taskinstance.py:2698} ERROR - Task failed with exception
Traceback (most recent call last):
  File "/home/airflow/.local/lib/python3.8/site-packages/airflow/models/taskinstance.py", line 433, in _execute_task
    result = execute_callable(context=context, **execute_callable_kwargs)
  File "/home/airflow/.local/lib/python3.8/site-packages/airflow/operators/python.py", line 199, in execute
    return_value = self.execute_callable()
  File "/home/airflow/.local/lib/python3.8/site-packages/airflow/operators/python.py", line 216, in execute_callable
    return self.python_callable(*self.op_args, **self.op_kwargs)
  File "/opt/airflow/dags/etl_pipeline.py", line 197, in <lambda>
    python_callable=lambda: load_table(SqlQueries.time_table_insert, 'time'),
  File "/opt/airflow/dags/etl_pipeline.py", line 132, in load_table
    cur.execute(f"INSERT INTO {table} {query}")
psycopg2.errors.UniqueViolation: duplicate key value violates unique constraint "time_pkey"
DETAIL:  Key (start_time)=(2018-11-14 04:53:36) already exists.

[2025-07-24T16:34:55.649+0000] {taskinstance.py:1138} INFO - Marking task as UP_FOR_RETRY. dag_id=tune_stream_dag, task_id=Load_time_dim_table, execution_date=20230101T190000, start_date=20250724T163454, end_date=20250724T163455
[2025-07-24T16:34:55.683+0000] {standard_task_runner.py:107} ERROR - Failed to execute job 1640 for task Load_time_dim_table (duplicate key value violates unique constraint "time_pkey"
DETAIL:  Key (start_time)=(2018-11-14 04:53:36) already exists.
; 1311)
[2025-07-24T16:34:55.792+0000] {local_task_job_runner.py:234} INFO - Task exited with return code 1
[2025-07-24T16:34:55.931+0000] {taskinstance.py:3280} INFO - 0 downstream tasks scheduled from follow-on schedule check
[2025-07-24T17:13:38.488+0000] {taskinstance.py:1956} INFO - Dependencies all met for dep_context=non-requeueable deps ti=<TaskInstance: tune_stream_dag.Load_time_dim_table scheduled__2023-01-01T19:00:00+00:00 [queued]>
[2025-07-24T17:13:38.571+0000] {taskinstance.py:1956} INFO - Dependencies all met for dep_context=requeueable deps ti=<TaskInstance: tune_stream_dag.Load_time_dim_table scheduled__2023-01-01T19:00:00+00:00 [queued]>
[2025-07-24T17:13:38.584+0000] {taskinstance.py:2170} INFO - Starting attempt 1 of 4
[2025-07-24T17:13:38.627+0000] {taskinstance.py:2191} INFO - Executing <Task(PythonOperator): Load_time_dim_table> on 2023-01-01 19:00:00+00:00
[2025-07-24T17:13:38.665+0000] {standard_task_runner.py:87} INFO - Running: ['***', 'tasks', 'run', 'tune_stream_dag', 'Load_time_dim_table', 'scheduled__2023-01-01T19:00:00+00:00', '--job-id', '2024', '--raw', '--subdir', 'DAGS_FOLDER/etl_pipeline.py', '--cfg-path', '/tmp/tmpul55rnxc']
[2025-07-24T17:13:38.672+0000] {standard_task_runner.py:88} INFO - Job 2024: Subtask Load_time_dim_table
[2025-07-24T17:13:38.661+0000] {standard_task_runner.py:60} INFO - Started process 1261 to run task
[2025-07-24T17:13:39.072+0000] {task_command.py:423} INFO - Running <TaskInstance: tune_stream_dag.Load_time_dim_table scheduled__2023-01-01T19:00:00+00:00 [running]> on host 5def55d2a1b5
[2025-07-24T17:13:39.409+0000] {taskinstance.py:2480} INFO - Exporting env vars: AIRFLOW_CTX_DAG_OWNER='genz-legend' AIRFLOW_CTX_DAG_ID='tune_stream_dag' AIRFLOW_CTX_TASK_ID='Load_time_dim_table' AIRFLOW_CTX_EXECUTION_DATE='2023-01-01T19:00:00+00:00' AIRFLOW_CTX_TRY_NUMBER='1' AIRFLOW_CTX_DAG_RUN_ID='scheduled__2023-01-01T19:00:00+00:00'
[2025-07-24T17:13:39.518+0000] {taskinstance.py:2698} ERROR - Task failed with exception
Traceback (most recent call last):
  File "/home/airflow/.local/lib/python3.8/site-packages/airflow/models/taskinstance.py", line 433, in _execute_task
    result = execute_callable(context=context, **execute_callable_kwargs)
  File "/home/airflow/.local/lib/python3.8/site-packages/airflow/operators/python.py", line 199, in execute
    return_value = self.execute_callable()
  File "/home/airflow/.local/lib/python3.8/site-packages/airflow/operators/python.py", line 216, in execute_callable
    return self.python_callable(*self.op_args, **self.op_kwargs)
  File "/opt/airflow/dags/etl_pipeline.py", line 197, in <lambda>
    python_callable=lambda: load_table(SqlQueries.time_table_insert, 'time'),
  File "/opt/airflow/dags/etl_pipeline.py", line 132, in load_table
    cur.execute(f"INSERT INTO {table} {query}")
psycopg2.errors.UniqueViolation: duplicate key value violates unique constraint "time_pkey"
DETAIL:  Key (start_time)=(2018-11-14 04:53:36) already exists.

[2025-07-24T17:13:39.648+0000] {taskinstance.py:1138} INFO - Marking task as UP_FOR_RETRY. dag_id=tune_stream_dag, task_id=Load_time_dim_table, execution_date=20230101T190000, start_date=20250724T171338, end_date=20250724T171339
[2025-07-24T17:13:39.734+0000] {standard_task_runner.py:107} ERROR - Failed to execute job 2024 for task Load_time_dim_table (duplicate key value violates unique constraint "time_pkey"
DETAIL:  Key (start_time)=(2018-11-14 04:53:36) already exists.
; 1261)
[2025-07-24T17:13:39.883+0000] {local_task_job_runner.py:234} INFO - Task exited with return code 1
[2025-07-24T17:13:40.086+0000] {taskinstance.py:3280} INFO - 0 downstream tasks scheduled from follow-on schedule check
