[2025-07-24T15:49:13.595+0000] {taskinstance.py:1956} INFO - Dependencies all met for dep_context=non-requeueable deps ti=<TaskInstance: tune_stream_dag.Load_time_dim_table scheduled__2023-01-01T11:00:00+00:00 [queued]>
[2025-07-24T15:49:13.640+0000] {taskinstance.py:1956} INFO - Dependencies all met for dep_context=requeueable deps ti=<TaskInstance: tune_stream_dag.Load_time_dim_table scheduled__2023-01-01T11:00:00+00:00 [queued]>
[2025-07-24T15:49:13.647+0000] {taskinstance.py:2170} INFO - Starting attempt 4 of 4
[2025-07-24T15:49:13.719+0000] {taskinstance.py:2191} INFO - Executing <Task(PythonOperator): Load_time_dim_table> on 2023-01-01 11:00:00+00:00
[2025-07-24T15:49:13.774+0000] {standard_task_runner.py:60} INFO - Started process 921 to run task
[2025-07-24T15:49:13.788+0000] {standard_task_runner.py:87} INFO - Running: ['***', 'tasks', 'run', 'tune_stream_dag', 'Load_time_dim_table', 'scheduled__2023-01-01T11:00:00+00:00', '--job-id', '1135', '--raw', '--subdir', 'DAGS_FOLDER/etl_pipeline.py', '--cfg-path', '/tmp/tmpy9nt9_mf']
[2025-07-24T15:49:13.807+0000] {standard_task_runner.py:88} INFO - Job 1135: Subtask Load_time_dim_table
[2025-07-24T15:49:14.130+0000] {task_command.py:423} INFO - Running <TaskInstance: tune_stream_dag.Load_time_dim_table scheduled__2023-01-01T11:00:00+00:00 [running]> on host c53547d84df1
[2025-07-24T15:49:14.458+0000] {taskinstance.py:2480} INFO - Exporting env vars: AIRFLOW_CTX_DAG_OWNER='genz-legend' AIRFLOW_CTX_DAG_ID='tune_stream_dag' AIRFLOW_CTX_TASK_ID='Load_time_dim_table' AIRFLOW_CTX_EXECUTION_DATE='2023-01-01T11:00:00+00:00' AIRFLOW_CTX_TRY_NUMBER='4' AIRFLOW_CTX_DAG_RUN_ID='scheduled__2023-01-01T11:00:00+00:00'
[2025-07-24T15:49:14.501+0000] {taskinstance.py:2698} ERROR - Task failed with exception
Traceback (most recent call last):
  File "/home/airflow/.local/lib/python3.8/site-packages/airflow/models/taskinstance.py", line 433, in _execute_task
    result = execute_callable(context=context, **execute_callable_kwargs)
  File "/home/airflow/.local/lib/python3.8/site-packages/airflow/operators/python.py", line 199, in execute
    return_value = self.execute_callable()
  File "/home/airflow/.local/lib/python3.8/site-packages/airflow/operators/python.py", line 216, in execute_callable
    return self.python_callable(*self.op_args, **self.op_kwargs)
  File "/opt/airflow/dags/etl_pipeline.py", line 197, in <lambda>
    python_callable=lambda: load_table(SqlQueries.time_table_insert, 'time'),
  File "/opt/airflow/dags/etl_pipeline.py", line 132, in load_table
    cur.execute(f"INSERT INTO {table} {query}")
psycopg2.errors.InvalidParameterValue: timestamp units "dayofweek" not recognized

[2025-07-24T15:49:14.537+0000] {taskinstance.py:1138} INFO - Marking task as FAILED. dag_id=tune_stream_dag, task_id=Load_time_dim_table, execution_date=20230101T110000, start_date=20250724T154913, end_date=20250724T154914
[2025-07-24T15:49:14.565+0000] {standard_task_runner.py:107} ERROR - Failed to execute job 1135 for task Load_time_dim_table (timestamp units "dayofweek" not recognized
; 921)
[2025-07-24T15:49:14.603+0000] {local_task_job_runner.py:234} INFO - Task exited with return code 1
[2025-07-24T15:49:14.681+0000] {taskinstance.py:3280} INFO - 0 downstream tasks scheduled from follow-on schedule check
[2025-07-24T16:33:32.373+0000] {taskinstance.py:1956} INFO - Dependencies all met for dep_context=non-requeueable deps ti=<TaskInstance: tune_stream_dag.Load_time_dim_table scheduled__2023-01-01T11:00:00+00:00 [queued]>
[2025-07-24T16:33:32.431+0000] {taskinstance.py:1956} INFO - Dependencies all met for dep_context=requeueable deps ti=<TaskInstance: tune_stream_dag.Load_time_dim_table scheduled__2023-01-01T11:00:00+00:00 [queued]>
[2025-07-24T16:33:32.449+0000] {taskinstance.py:2170} INFO - Starting attempt 4 of 4
[2025-07-24T16:33:32.582+0000] {taskinstance.py:2191} INFO - Executing <Task(PythonOperator): Load_time_dim_table> on 2023-01-01 11:00:00+00:00
[2025-07-24T16:33:32.637+0000] {standard_task_runner.py:60} INFO - Started process 1068 to run task
[2025-07-24T16:33:32.663+0000] {standard_task_runner.py:87} INFO - Running: ['***', 'tasks', 'run', 'tune_stream_dag', 'Load_time_dim_table', 'scheduled__2023-01-01T11:00:00+00:00', '--job-id', '1568', '--raw', '--subdir', 'DAGS_FOLDER/etl_pipeline.py', '--cfg-path', '/tmp/tmpz65jqilb']
[2025-07-24T16:33:32.686+0000] {standard_task_runner.py:88} INFO - Job 1568: Subtask Load_time_dim_table
[2025-07-24T16:33:33.680+0000] {task_command.py:423} INFO - Running <TaskInstance: tune_stream_dag.Load_time_dim_table scheduled__2023-01-01T11:00:00+00:00 [running]> on host c53547d84df1
[2025-07-24T16:33:33.899+0000] {taskinstance.py:2480} INFO - Exporting env vars: AIRFLOW_CTX_DAG_OWNER='genz-legend' AIRFLOW_CTX_DAG_ID='tune_stream_dag' AIRFLOW_CTX_TASK_ID='Load_time_dim_table' AIRFLOW_CTX_EXECUTION_DATE='2023-01-01T11:00:00+00:00' AIRFLOW_CTX_TRY_NUMBER='4' AIRFLOW_CTX_DAG_RUN_ID='scheduled__2023-01-01T11:00:00+00:00'
[2025-07-24T16:33:33.971+0000] {taskinstance.py:2698} ERROR - Task failed with exception
Traceback (most recent call last):
  File "/home/airflow/.local/lib/python3.8/site-packages/airflow/models/taskinstance.py", line 433, in _execute_task
    result = execute_callable(context=context, **execute_callable_kwargs)
  File "/home/airflow/.local/lib/python3.8/site-packages/airflow/operators/python.py", line 199, in execute
    return_value = self.execute_callable()
  File "/home/airflow/.local/lib/python3.8/site-packages/airflow/operators/python.py", line 216, in execute_callable
    return self.python_callable(*self.op_args, **self.op_kwargs)
  File "/opt/airflow/dags/etl_pipeline.py", line 197, in <lambda>
    python_callable=lambda: load_table(SqlQueries.time_table_insert, 'time'),
  File "/opt/airflow/dags/etl_pipeline.py", line 132, in load_table
    cur.execute(f"INSERT INTO {table} {query}")
psycopg2.errors.UniqueViolation: duplicate key value violates unique constraint "time_pkey"
DETAIL:  Key (start_time)=(2018-11-14 04:53:36) already exists.

[2025-07-24T16:33:34.004+0000] {taskinstance.py:1138} INFO - Marking task as FAILED. dag_id=tune_stream_dag, task_id=Load_time_dim_table, execution_date=20230101T110000, start_date=20250724T163332, end_date=20250724T163334
[2025-07-24T16:33:34.038+0000] {standard_task_runner.py:107} ERROR - Failed to execute job 1568 for task Load_time_dim_table (duplicate key value violates unique constraint "time_pkey"
DETAIL:  Key (start_time)=(2018-11-14 04:53:36) already exists.
; 1068)
[2025-07-24T16:33:34.114+0000] {local_task_job_runner.py:234} INFO - Task exited with return code 1
[2025-07-24T16:33:34.306+0000] {taskinstance.py:3280} INFO - 0 downstream tasks scheduled from follow-on schedule check
[2025-07-24T17:12:34.034+0000] {taskinstance.py:1956} INFO - Dependencies all met for dep_context=non-requeueable deps ti=<TaskInstance: tune_stream_dag.Load_time_dim_table scheduled__2023-01-01T11:00:00+00:00 [queued]>
[2025-07-24T17:12:34.042+0000] {taskinstance.py:1956} INFO - Dependencies all met for dep_context=requeueable deps ti=<TaskInstance: tune_stream_dag.Load_time_dim_table scheduled__2023-01-01T11:00:00+00:00 [queued]>
[2025-07-24T17:12:34.043+0000] {taskinstance.py:2170} INFO - Starting attempt 4 of 4
[2025-07-24T17:12:34.054+0000] {taskinstance.py:2191} INFO - Executing <Task(PythonOperator): Load_time_dim_table> on 2023-01-01 11:00:00+00:00
[2025-07-24T17:12:34.059+0000] {standard_task_runner.py:60} INFO - Started process 1039 to run task
[2025-07-24T17:12:34.062+0000] {standard_task_runner.py:87} INFO - Running: ['***', 'tasks', 'run', 'tune_stream_dag', 'Load_time_dim_table', 'scheduled__2023-01-01T11:00:00+00:00', '--job-id', '1960', '--raw', '--subdir', 'DAGS_FOLDER/etl_pipeline.py', '--cfg-path', '/tmp/tmpe5btt8d9']
[2025-07-24T17:12:34.065+0000] {standard_task_runner.py:88} INFO - Job 1960: Subtask Load_time_dim_table
[2025-07-24T17:12:34.126+0000] {task_command.py:423} INFO - Running <TaskInstance: tune_stream_dag.Load_time_dim_table scheduled__2023-01-01T11:00:00+00:00 [running]> on host 5def55d2a1b5
[2025-07-24T17:12:34.192+0000] {taskinstance.py:2480} INFO - Exporting env vars: AIRFLOW_CTX_DAG_OWNER='genz-legend' AIRFLOW_CTX_DAG_ID='tune_stream_dag' AIRFLOW_CTX_TASK_ID='Load_time_dim_table' AIRFLOW_CTX_EXECUTION_DATE='2023-01-01T11:00:00+00:00' AIRFLOW_CTX_TRY_NUMBER='4' AIRFLOW_CTX_DAG_RUN_ID='scheduled__2023-01-01T11:00:00+00:00'
[2025-07-24T17:12:34.210+0000] {taskinstance.py:2698} ERROR - Task failed with exception
Traceback (most recent call last):
  File "/home/airflow/.local/lib/python3.8/site-packages/airflow/models/taskinstance.py", line 433, in _execute_task
    result = execute_callable(context=context, **execute_callable_kwargs)
  File "/home/airflow/.local/lib/python3.8/site-packages/airflow/operators/python.py", line 199, in execute
    return_value = self.execute_callable()
  File "/home/airflow/.local/lib/python3.8/site-packages/airflow/operators/python.py", line 216, in execute_callable
    return self.python_callable(*self.op_args, **self.op_kwargs)
  File "/opt/airflow/dags/etl_pipeline.py", line 197, in <lambda>
    python_callable=lambda: load_table(SqlQueries.time_table_insert, 'time'),
  File "/opt/airflow/dags/etl_pipeline.py", line 132, in load_table
    cur.execute(f"INSERT INTO {table} {query}")
psycopg2.errors.UniqueViolation: duplicate key value violates unique constraint "time_pkey"
DETAIL:  Key (start_time)=(2018-11-14 04:53:36) already exists.

[2025-07-24T17:12:34.221+0000] {taskinstance.py:1138} INFO - Marking task as FAILED. dag_id=tune_stream_dag, task_id=Load_time_dim_table, execution_date=20230101T110000, start_date=20250724T171234, end_date=20250724T171234
[2025-07-24T17:12:34.232+0000] {standard_task_runner.py:107} ERROR - Failed to execute job 1960 for task Load_time_dim_table (duplicate key value violates unique constraint "time_pkey"
DETAIL:  Key (start_time)=(2018-11-14 04:53:36) already exists.
; 1039)
[2025-07-24T17:12:34.276+0000] {local_task_job_runner.py:234} INFO - Task exited with return code 1
[2025-07-24T17:12:34.300+0000] {taskinstance.py:3280} INFO - 0 downstream tasks scheduled from follow-on schedule check
