[2025-07-24T15:54:47.055+0000] {taskinstance.py:1956} INFO - Dependencies all met for dep_context=non-requeueable deps ti=<TaskInstance: tune_stream_dag.Load_user_dim_table scheduled__2023-01-01T21:00:00+00:00 [queued]>
[2025-07-24T15:54:47.076+0000] {taskinstance.py:1956} INFO - Dependencies all met for dep_context=requeueable deps ti=<TaskInstance: tune_stream_dag.Load_user_dim_table scheduled__2023-01-01T21:00:00+00:00 [queued]>
[2025-07-24T15:54:47.078+0000] {taskinstance.py:2170} INFO - Starting attempt 2 of 4
[2025-07-24T15:54:47.104+0000] {taskinstance.py:2191} INFO - Executing <Task(PythonOperator): Load_user_dim_table> on 2023-01-01 21:00:00+00:00
[2025-07-24T15:54:47.124+0000] {standard_task_runner.py:60} INFO - Started process 1227 to run task
[2025-07-24T15:54:47.137+0000] {standard_task_runner.py:87} INFO - Running: ['***', 'tasks', 'run', 'tune_stream_dag', 'Load_user_dim_table', 'scheduled__2023-01-01T21:00:00+00:00', '--job-id', '1215', '--raw', '--subdir', 'DAGS_FOLDER/etl_pipeline.py', '--cfg-path', '/tmp/tmpju1sowrx']
[2025-07-24T15:54:47.142+0000] {standard_task_runner.py:88} INFO - Job 1215: Subtask Load_user_dim_table
[2025-07-24T15:54:47.247+0000] {task_command.py:423} INFO - Running <TaskInstance: tune_stream_dag.Load_user_dim_table scheduled__2023-01-01T21:00:00+00:00 [running]> on host c53547d84df1
[2025-07-24T15:54:47.357+0000] {taskinstance.py:2480} INFO - Exporting env vars: AIRFLOW_CTX_DAG_OWNER='genz-legend' AIRFLOW_CTX_DAG_ID='tune_stream_dag' AIRFLOW_CTX_TASK_ID='Load_user_dim_table' AIRFLOW_CTX_EXECUTION_DATE='2023-01-01T21:00:00+00:00' AIRFLOW_CTX_TRY_NUMBER='2' AIRFLOW_CTX_DAG_RUN_ID='scheduled__2023-01-01T21:00:00+00:00'
[2025-07-24T15:54:47.377+0000] {taskinstance.py:2698} ERROR - Task failed with exception
Traceback (most recent call last):
  File "/home/airflow/.local/lib/python3.8/site-packages/airflow/models/taskinstance.py", line 433, in _execute_task
    result = execute_callable(context=context, **execute_callable_kwargs)
  File "/home/airflow/.local/lib/python3.8/site-packages/airflow/operators/python.py", line 199, in execute
    return_value = self.execute_callable()
  File "/home/airflow/.local/lib/python3.8/site-packages/airflow/operators/python.py", line 216, in execute_callable
    return self.python_callable(*self.op_args, **self.op_kwargs)
  File "/opt/airflow/dags/etl_pipeline.py", line 179, in <lambda>
    python_callable=lambda: load_table(SqlQueries.user_table_insert, 'users'),
  File "/opt/airflow/dags/etl_pipeline.py", line 132, in load_table
    cur.execute(f"INSERT INTO {table} {query}")
psycopg2.errors.UniqueViolation: duplicate key value violates unique constraint "users_pkey"
DETAIL:  Key (userid)=(88) already exists.

[2025-07-24T15:54:47.396+0000] {taskinstance.py:1138} INFO - Marking task as UP_FOR_RETRY. dag_id=tune_stream_dag, task_id=Load_user_dim_table, execution_date=20230101T210000, start_date=20250724T155447, end_date=20250724T155447
[2025-07-24T15:54:47.419+0000] {standard_task_runner.py:107} ERROR - Failed to execute job 1215 for task Load_user_dim_table (duplicate key value violates unique constraint "users_pkey"
DETAIL:  Key (userid)=(88) already exists.
; 1227)
[2025-07-24T15:54:47.470+0000] {local_task_job_runner.py:234} INFO - Task exited with return code 1
[2025-07-24T15:54:49.807+0000] {taskinstance.py:3280} INFO - 0 downstream tasks scheduled from follow-on schedule check
[2025-07-24T16:42:00.349+0000] {taskinstance.py:1956} INFO - Dependencies all met for dep_context=non-requeueable deps ti=<TaskInstance: tune_stream_dag.Load_user_dim_table scheduled__2023-01-01T21:00:00+00:00 [queued]>
[2025-07-24T16:42:00.397+0000] {taskinstance.py:1956} INFO - Dependencies all met for dep_context=requeueable deps ti=<TaskInstance: tune_stream_dag.Load_user_dim_table scheduled__2023-01-01T21:00:00+00:00 [queued]>
[2025-07-24T16:42:00.398+0000] {taskinstance.py:2170} INFO - Starting attempt 2 of 4
[2025-07-24T16:42:00.440+0000] {taskinstance.py:2191} INFO - Executing <Task(PythonOperator): Load_user_dim_table> on 2023-01-01 21:00:00+00:00
[2025-07-24T16:42:00.656+0000] {standard_task_runner.py:60} INFO - Started process 128 to run task
[2025-07-24T16:42:00.722+0000] {standard_task_runner.py:87} INFO - Running: ['***', 'tasks', 'run', 'tune_stream_dag', 'Load_user_dim_table', 'scheduled__2023-01-01T21:00:00+00:00', '--job-id', '1682', '--raw', '--subdir', 'DAGS_FOLDER/etl_pipeline.py', '--cfg-path', '/tmp/tmpquhtilrd']
[2025-07-24T16:42:00.766+0000] {standard_task_runner.py:88} INFO - Job 1682: Subtask Load_user_dim_table
[2025-07-24T16:42:01.560+0000] {task_command.py:423} INFO - Running <TaskInstance: tune_stream_dag.Load_user_dim_table scheduled__2023-01-01T21:00:00+00:00 [running]> on host 5def55d2a1b5
[2025-07-24T16:42:02.302+0000] {taskinstance.py:2480} INFO - Exporting env vars: AIRFLOW_CTX_DAG_OWNER='genz-legend' AIRFLOW_CTX_DAG_ID='tune_stream_dag' AIRFLOW_CTX_TASK_ID='Load_user_dim_table' AIRFLOW_CTX_EXECUTION_DATE='2023-01-01T21:00:00+00:00' AIRFLOW_CTX_TRY_NUMBER='2' AIRFLOW_CTX_DAG_RUN_ID='scheduled__2023-01-01T21:00:00+00:00'
[2025-07-24T16:42:02.496+0000] {taskinstance.py:2698} ERROR - Task failed with exception
Traceback (most recent call last):
  File "/home/airflow/.local/lib/python3.8/site-packages/airflow/models/taskinstance.py", line 433, in _execute_task
    result = execute_callable(context=context, **execute_callable_kwargs)
  File "/home/airflow/.local/lib/python3.8/site-packages/airflow/operators/python.py", line 199, in execute
    return_value = self.execute_callable()
  File "/home/airflow/.local/lib/python3.8/site-packages/airflow/operators/python.py", line 216, in execute_callable
    return self.python_callable(*self.op_args, **self.op_kwargs)
  File "/opt/airflow/dags/etl_pipeline.py", line 179, in <lambda>
    python_callable=lambda: load_table(SqlQueries.user_table_insert, 'users'),
  File "/opt/airflow/dags/etl_pipeline.py", line 132, in load_table
    cur.execute(f"INSERT INTO {table} {query}")
psycopg2.errors.UniqueViolation: duplicate key value violates unique constraint "users_pkey"
DETAIL:  Key (userid)=(88) already exists.

[2025-07-24T16:42:02.701+0000] {taskinstance.py:1138} INFO - Marking task as UP_FOR_RETRY. dag_id=tune_stream_dag, task_id=Load_user_dim_table, execution_date=20230101T210000, start_date=20250724T164200, end_date=20250724T164202
[2025-07-24T16:42:02.755+0000] {standard_task_runner.py:107} ERROR - Failed to execute job 1682 for task Load_user_dim_table (duplicate key value violates unique constraint "users_pkey"
DETAIL:  Key (userid)=(88) already exists.
; 128)
[2025-07-24T16:42:02.801+0000] {local_task_job_runner.py:234} INFO - Task exited with return code 1
[2025-07-24T16:42:03.004+0000] {taskinstance.py:3280} INFO - 0 downstream tasks scheduled from follow-on schedule check
[2025-07-24T17:18:40.283+0000] {taskinstance.py:1956} INFO - Dependencies all met for dep_context=non-requeueable deps ti=<TaskInstance: tune_stream_dag.Load_user_dim_table scheduled__2023-01-01T21:00:00+00:00 [queued]>
[2025-07-24T17:18:40.303+0000] {taskinstance.py:1956} INFO - Dependencies all met for dep_context=requeueable deps ti=<TaskInstance: tune_stream_dag.Load_user_dim_table scheduled__2023-01-01T21:00:00+00:00 [queued]>
[2025-07-24T17:18:40.305+0000] {taskinstance.py:2170} INFO - Starting attempt 2 of 4
[2025-07-24T17:18:40.332+0000] {taskinstance.py:2191} INFO - Executing <Task(PythonOperator): Load_user_dim_table> on 2023-01-01 21:00:00+00:00
[2025-07-24T17:18:40.346+0000] {standard_task_runner.py:60} INFO - Started process 1685 to run task
[2025-07-24T17:18:40.353+0000] {standard_task_runner.py:87} INFO - Running: ['***', 'tasks', 'run', 'tune_stream_dag', 'Load_user_dim_table', 'scheduled__2023-01-01T21:00:00+00:00', '--job-id', '2145', '--raw', '--subdir', 'DAGS_FOLDER/etl_pipeline.py', '--cfg-path', '/tmp/tmp2t2pdgs8']
[2025-07-24T17:18:40.358+0000] {standard_task_runner.py:88} INFO - Job 2145: Subtask Load_user_dim_table
[2025-07-24T17:18:40.460+0000] {task_command.py:423} INFO - Running <TaskInstance: tune_stream_dag.Load_user_dim_table scheduled__2023-01-01T21:00:00+00:00 [running]> on host 5def55d2a1b5
[2025-07-24T17:18:40.565+0000] {taskinstance.py:2480} INFO - Exporting env vars: AIRFLOW_CTX_DAG_OWNER='genz-legend' AIRFLOW_CTX_DAG_ID='tune_stream_dag' AIRFLOW_CTX_TASK_ID='Load_user_dim_table' AIRFLOW_CTX_EXECUTION_DATE='2023-01-01T21:00:00+00:00' AIRFLOW_CTX_TRY_NUMBER='2' AIRFLOW_CTX_DAG_RUN_ID='scheduled__2023-01-01T21:00:00+00:00'
[2025-07-24T17:18:40.598+0000] {python.py:201} INFO - Done. Returned value was: None
[2025-07-24T17:18:40.614+0000] {taskinstance.py:1138} INFO - Marking task as SUCCESS. dag_id=tune_stream_dag, task_id=Load_user_dim_table, execution_date=20230101T210000, start_date=20250724T171840, end_date=20250724T171840
[2025-07-24T17:18:40.687+0000] {local_task_job_runner.py:234} INFO - Task exited with return code 0
[2025-07-24T17:18:40.842+0000] {taskinstance.py:3280} INFO - 0 downstream tasks scheduled from follow-on schedule check
