[2025-07-24T17:12:37.315+0000] {taskinstance.py:1956} INFO - Dependencies all met for dep_context=non-requeueable deps ti=<TaskInstance: tune_stream_dag.Load_user_dim_table manual__2025-07-24T16:54:19.482432+00:00 [queued]>
[2025-07-24T17:12:37.336+0000] {taskinstance.py:1956} INFO - Dependencies all met for dep_context=requeueable deps ti=<TaskInstance: tune_stream_dag.Load_user_dim_table manual__2025-07-24T16:54:19.482432+00:00 [queued]>
[2025-07-24T17:12:37.337+0000] {taskinstance.py:2170} INFO - Starting attempt 4 of 4
[2025-07-24T17:12:37.359+0000] {taskinstance.py:2191} INFO - Executing <Task(PythonOperator): Load_user_dim_table> on 2025-07-24 16:54:19.482432+00:00
[2025-07-24T17:12:37.379+0000] {standard_task_runner.py:60} INFO - Started process 1058 to run task
[2025-07-24T17:12:37.392+0000] {standard_task_runner.py:87} INFO - Running: ['***', 'tasks', 'run', 'tune_stream_dag', 'Load_user_dim_table', 'manual__2025-07-24T16:54:19.482432+00:00', '--job-id', '1965', '--raw', '--subdir', 'DAGS_FOLDER/etl_pipeline.py', '--cfg-path', '/tmp/tmp9oain5sj']
[2025-07-24T17:12:37.401+0000] {standard_task_runner.py:88} INFO - Job 1965: Subtask Load_user_dim_table
[2025-07-24T17:12:37.660+0000] {task_command.py:423} INFO - Running <TaskInstance: tune_stream_dag.Load_user_dim_table manual__2025-07-24T16:54:19.482432+00:00 [running]> on host 5def55d2a1b5
[2025-07-24T17:12:37.989+0000] {taskinstance.py:2480} INFO - Exporting env vars: AIRFLOW_CTX_DAG_OWNER='genz-legend' AIRFLOW_CTX_DAG_ID='tune_stream_dag' AIRFLOW_CTX_TASK_ID='Load_user_dim_table' AIRFLOW_CTX_EXECUTION_DATE='2025-07-24T16:54:19.482432+00:00' AIRFLOW_CTX_TRY_NUMBER='4' AIRFLOW_CTX_DAG_RUN_ID='manual__2025-07-24T16:54:19.482432+00:00'
[2025-07-24T17:12:38.044+0000] {taskinstance.py:2698} ERROR - Task failed with exception
Traceback (most recent call last):
  File "/home/airflow/.local/lib/python3.8/site-packages/airflow/models/taskinstance.py", line 433, in _execute_task
    result = execute_callable(context=context, **execute_callable_kwargs)
  File "/home/airflow/.local/lib/python3.8/site-packages/airflow/operators/python.py", line 199, in execute
    return_value = self.execute_callable()
  File "/home/airflow/.local/lib/python3.8/site-packages/airflow/operators/python.py", line 216, in execute_callable
    return self.python_callable(*self.op_args, **self.op_kwargs)
  File "/opt/airflow/dags/etl_pipeline.py", line 179, in <lambda>
    python_callable=lambda: load_table(SqlQueries.user_table_insert, 'users'),
  File "/opt/airflow/dags/etl_pipeline.py", line 132, in load_table
    cur.execute(f"INSERT INTO {table} {query}")
psycopg2.errors.UniqueViolation: duplicate key value violates unique constraint "users_pkey"
DETAIL:  Key (userid)=(88) already exists.

[2025-07-24T17:12:38.068+0000] {taskinstance.py:1138} INFO - Marking task as FAILED. dag_id=tune_stream_dag, task_id=Load_user_dim_table, execution_date=20250724T165419, start_date=20250724T171237, end_date=20250724T171238
[2025-07-24T17:12:38.094+0000] {standard_task_runner.py:107} ERROR - Failed to execute job 1965 for task Load_user_dim_table (duplicate key value violates unique constraint "users_pkey"
DETAIL:  Key (userid)=(88) already exists.
; 1058)
[2025-07-24T17:12:38.136+0000] {local_task_job_runner.py:234} INFO - Task exited with return code 1
[2025-07-24T17:12:38.174+0000] {taskinstance.py:3280} INFO - 0 downstream tasks scheduled from follow-on schedule check
